2025-07-07 08:33:19,470 - root - INFO - 🔧 Using Replit-specific entry point
2025-07-07 08:33:19,470 - root - INFO - === QUIZ BOT STARTING ===
2025-07-07 08:33:19,470 - root - INFO - Python version: 3.13.3 (main, Apr  8 2025, 19:55:40) [GCC 14.2.0]
2025-07-07 08:33:19,470 - root - INFO - Environment debug info:
2025-07-07 08:33:19,470 - root - INFO -   Is Replit: False
2025-07-07 08:33:19,471 - root - INFO -   Replit URL: None
2025-07-07 08:33:19,471 - root - INFO - Initializing database...
2025-07-07 08:33:19,500 - root - INFO - Database initialized successfully
2025-07-07 08:33:19,500 - root - INFO - OpenAI API key loaded successfully
2025-07-07 08:33:19,500 - root - INFO - Creating Telegram application...
2025-07-07 08:33:19,548 - root - INFO - Telegram application created successfully
2025-07-07 08:33:19,548 - root - INFO - Registering handlers...
2025-07-07 08:33:19,549 - root - INFO - Handlers registered successfully
2025-07-07 08:33:19,549 - root - INFO - No webhook configured, will use polling mode
2025-07-07 08:33:19,549 - root - INFO - 📡 Starting polling mode...
2025-07-07 08:33:19,825 - httpx - INFO - HTTP Request: POST https://api.telegram.org/bot8082065832:AAFMg57PUuHJzTt2YavoqCK5pEBYlhpVdYg/getMe "HTTP/1.1 200 OK"
2025-07-07 08:33:19,917 - httpx - INFO - HTTP Request: POST https://api.telegram.org/bot8082065832:AAFMg57PUuHJzTt2YavoqCK5pEBYlhpVdYg/deleteWebhook "HTTP/1.1 200 OK"
2025-07-07 08:33:19,918 - telegram.ext.Application - INFO - Application started
2025-07-07 08:33:30,171 - httpx - INFO - HTTP Request: POST https://api.telegram.org/bot8082065832:AAFMg57PUuHJzTt2YavoqCK5pEBYlhpVdYg/getUpdates "HTTP/1.1 200 OK"
2025-07-07 08:33:40,256 - httpx - INFO - HTTP Request: POST https://api.telegram.org/bot8082065832:AAFMg57PUuHJzTt2YavoqCK5pEBYlhpVdYg/getUpdates "HTTP/1.1 200 OK"
2025-07-07 08:33:50,342 - httpx - INFO - HTTP Request: POST https://api.telegram.org/bot8082065832:AAFMg57PUuHJzTt2YavoqCK5pEBYlhpVdYg/getUpdates "HTTP/1.1 200 OK"
2025-07-07 08:34:00,443 - httpx - INFO - HTTP Request: POST https://api.telegram.org/bot8082065832:AAFMg57PUuHJzTt2YavoqCK5pEBYlhpVdYg/getUpdates "HTTP/1.1 200 OK"
2025-07-07 08:34:10,528 - httpx - INFO - HTTP Request: POST https://api.telegram.org/bot8082065832:AAFMg57PUuHJzTt2YavoqCK5pEBYlhpVdYg/getUpdates "HTTP/1.1 200 OK"
2025-07-07 08:34:20,616 - httpx - INFO - HTTP Request: POST https://api.telegram.org/bot8082065832:AAFMg57PUuHJzTt2YavoqCK5pEBYlhpVdYg/getUpdates "HTTP/1.1 200 OK"
2025-07-07 08:34:30,702 - httpx - INFO - HTTP Request: POST https://api.telegram.org/bot8082065832:AAFMg57PUuHJzTt2YavoqCK5pEBYlhpVdYg/getUpdates "HTTP/1.1 200 OK"
2025-07-07 08:34:40,787 - httpx - INFO - HTTP Request: POST https://api.telegram.org/bot8082065832:AAFMg57PUuHJzTt2YavoqCK5pEBYlhpVdYg/getUpdates "HTTP/1.1 200 OK"
2025-07-07 08:34:50,873 - httpx - INFO - HTTP Request: POST https://api.telegram.org/bot8082065832:AAFMg57PUuHJzTt2YavoqCK5pEBYlhpVdYg/getUpdates "HTTP/1.1 200 OK"
2025-07-07 08:35:00,958 - httpx - INFO - HTTP Request: POST https://api.telegram.org/bot8082065832:AAFMg57PUuHJzTt2YavoqCK5pEBYlhpVdYg/getUpdates "HTTP/1.1 200 OK"
2025-07-07 08:35:11,065 - httpx - INFO - HTTP Request: POST https://api.telegram.org/bot8082065832:AAFMg57PUuHJzTt2YavoqCK5pEBYlhpVdYg/getUpdates "HTTP/1.1 200 OK"
2025-07-07 08:35:21,151 - httpx - INFO - HTTP Request: POST https://api.telegram.org/bot8082065832:AAFMg57PUuHJzTt2YavoqCK5pEBYlhpVdYg/getUpdates "HTTP/1.1 200 OK"
2025-07-07 08:35:31,237 - httpx - INFO - HTTP Request: POST https://api.telegram.org/bot8082065832:AAFMg57PUuHJzTt2YavoqCK5pEBYlhpVdYg/getUpdates "HTTP/1.1 200 OK"
2025-07-07 08:35:41,323 - httpx - INFO - HTTP Request: POST https://api.telegram.org/bot8082065832:AAFMg57PUuHJzTt2YavoqCK5pEBYlhpVdYg/getUpdates "HTTP/1.1 200 OK"
2025-07-07 08:35:51,409 - httpx - INFO - HTTP Request: POST https://api.telegram.org/bot8082065832:AAFMg57PUuHJzTt2YavoqCK5pEBYlhpVdYg/getUpdates "HTTP/1.1 200 OK"
2025-07-07 08:36:01,507 - httpx - INFO - HTTP Request: POST https://api.telegram.org/bot8082065832:AAFMg57PUuHJzTt2YavoqCK5pEBYlhpVdYg/getUpdates "HTTP/1.1 200 OK"
2025-07-07 08:36:11,592 - httpx - INFO - HTTP Request: POST https://api.telegram.org/bot8082065832:AAFMg57PUuHJzTt2YavoqCK5pEBYlhpVdYg/getUpdates "HTTP/1.1 200 OK"
2025-07-07 08:36:21,678 - httpx - INFO - HTTP Request: POST https://api.telegram.org/bot8082065832:AAFMg57PUuHJzTt2YavoqCK5pEBYlhpVdYg/getUpdates "HTTP/1.1 200 OK"
2025-07-07 08:36:31,763 - httpx - INFO - HTTP Request: POST https://api.telegram.org/bot8082065832:AAFMg57PUuHJzTt2YavoqCK5pEBYlhpVdYg/getUpdates "HTTP/1.1 200 OK"
2025-07-07 08:36:41,852 - httpx - INFO - HTTP Request: POST https://api.telegram.org/bot8082065832:AAFMg57PUuHJzTt2YavoqCK5pEBYlhpVdYg/getUpdates "HTTP/1.1 200 OK"
2025-07-07 08:36:51,939 - httpx - INFO - HTTP Request: POST https://api.telegram.org/bot8082065832:AAFMg57PUuHJzTt2YavoqCK5pEBYlhpVdYg/getUpdates "HTTP/1.1 200 OK"
2025-07-07 08:37:02,024 - httpx - INFO - HTTP Request: POST https://api.telegram.org/bot8082065832:AAFMg57PUuHJzTt2YavoqCK5pEBYlhpVdYg/getUpdates "HTTP/1.1 200 OK"
2025-07-07 08:37:12,110 - httpx - INFO - HTTP Request: POST https://api.telegram.org/bot8082065832:AAFMg57PUuHJzTt2YavoqCK5pEBYlhpVdYg/getUpdates "HTTP/1.1 200 OK"
2025-07-07 08:37:22,197 - httpx - INFO - HTTP Request: POST https://api.telegram.org/bot8082065832:AAFMg57PUuHJzTt2YavoqCK5pEBYlhpVdYg/getUpdates "HTTP/1.1 200 OK"
2025-07-07 08:37:32,285 - httpx - INFO - HTTP Request: POST https://api.telegram.org/bot8082065832:AAFMg57PUuHJzTt2YavoqCK5pEBYlhpVdYg/getUpdates "HTTP/1.1 200 OK"
2025-07-07 08:37:42,370 - httpx - INFO - HTTP Request: POST https://api.telegram.org/bot8082065832:AAFMg57PUuHJzTt2YavoqCK5pEBYlhpVdYg/getUpdates "HTTP/1.1 200 OK"
2025-07-07 08:37:52,455 - httpx - INFO - HTTP Request: POST https://api.telegram.org/bot8082065832:AAFMg57PUuHJzTt2YavoqCK5pEBYlhpVdYg/getUpdates "HTTP/1.1 200 OK"
2025-07-07 08:38:02,541 - httpx - INFO - HTTP Request: POST https://api.telegram.org/bot8082065832:AAFMg57PUuHJzTt2YavoqCK5pEBYlhpVdYg/getUpdates "HTTP/1.1 200 OK"
2025-07-07 08:38:12,628 - httpx - INFO - HTTP Request: POST https://api.telegram.org/bot8082065832:AAFMg57PUuHJzTt2YavoqCK5pEBYlhpVdYg/getUpdates "HTTP/1.1 200 OK"
2025-07-07 08:38:22,716 - httpx - INFO - HTTP Request: POST https://api.telegram.org/bot8082065832:AAFMg57PUuHJzTt2YavoqCK5pEBYlhpVdYg/getUpdates "HTTP/1.1 200 OK"
2025-07-07 08:38:32,801 - httpx - INFO - HTTP Request: POST https://api.telegram.org/bot8082065832:AAFMg57PUuHJzTt2YavoqCK5pEBYlhpVdYg/getUpdates "HTTP/1.1 200 OK"
2025-07-07 08:38:42,887 - httpx - INFO - HTTP Request: POST https://api.telegram.org/bot8082065832:AAFMg57PUuHJzTt2YavoqCK5pEBYlhpVdYg/getUpdates "HTTP/1.1 200 OK"
2025-07-07 08:38:52,972 - httpx - INFO - HTTP Request: POST https://api.telegram.org/bot8082065832:AAFMg57PUuHJzTt2YavoqCK5pEBYlhpVdYg/getUpdates "HTTP/1.1 200 OK"
2025-07-07 08:39:03,058 - httpx - INFO - HTTP Request: POST https://api.telegram.org/bot8082065832:AAFMg57PUuHJzTt2YavoqCK5pEBYlhpVdYg/getUpdates "HTTP/1.1 200 OK"
2025-07-07 08:39:13,154 - httpx - INFO - HTTP Request: POST https://api.telegram.org/bot8082065832:AAFMg57PUuHJzTt2YavoqCK5pEBYlhpVdYg/getUpdates "HTTP/1.1 200 OK"
2025-07-07 08:39:23,240 - httpx - INFO - HTTP Request: POST https://api.telegram.org/bot8082065832:AAFMg57PUuHJzTt2YavoqCK5pEBYlhpVdYg/getUpdates "HTTP/1.1 200 OK"
2025-07-07 08:39:33,325 - httpx - INFO - HTTP Request: POST https://api.telegram.org/bot8082065832:AAFMg57PUuHJzTt2YavoqCK5pEBYlhpVdYg/getUpdates "HTTP/1.1 200 OK"
2025-07-07 08:39:43,411 - httpx - INFO - HTTP Request: POST https://api.telegram.org/bot8082065832:AAFMg57PUuHJzTt2YavoqCK5pEBYlhpVdYg/getUpdates "HTTP/1.1 200 OK"
2025-07-07 08:39:53,510 - httpx - INFO - HTTP Request: POST https://api.telegram.org/bot8082065832:AAFMg57PUuHJzTt2YavoqCK5pEBYlhpVdYg/getUpdates "HTTP/1.1 200 OK"
2025-07-07 08:40:03,595 - httpx - INFO - HTTP Request: POST https://api.telegram.org/bot8082065832:AAFMg57PUuHJzTt2YavoqCK5pEBYlhpVdYg/getUpdates "HTTP/1.1 200 OK"
2025-07-07 08:40:13,680 - httpx - INFO - HTTP Request: POST https://api.telegram.org/bot8082065832:AAFMg57PUuHJzTt2YavoqCK5pEBYlhpVdYg/getUpdates "HTTP/1.1 200 OK"
2025-07-07 08:40:23,768 - httpx - INFO - HTTP Request: POST https://api.telegram.org/bot8082065832:AAFMg57PUuHJzTt2YavoqCK5pEBYlhpVdYg/getUpdates "HTTP/1.1 200 OK"
2025-07-07 08:40:33,854 - httpx - INFO - HTTP Request: POST https://api.telegram.org/bot8082065832:AAFMg57PUuHJzTt2YavoqCK5pEBYlhpVdYg/getUpdates "HTTP/1.1 200 OK"
2025-07-07 08:40:43,940 - httpx - INFO - HTTP Request: POST https://api.telegram.org/bot8082065832:AAFMg57PUuHJzTt2YavoqCK5pEBYlhpVdYg/getUpdates "HTTP/1.1 200 OK"
2025-07-07 08:40:54,025 - httpx - INFO - HTTP Request: POST https://api.telegram.org/bot8082065832:AAFMg57PUuHJzTt2YavoqCK5pEBYlhpVdYg/getUpdates "HTTP/1.1 200 OK"
2025-07-07 08:41:04,109 - httpx - INFO - HTTP Request: POST https://api.telegram.org/bot8082065832:AAFMg57PUuHJzTt2YavoqCK5pEBYlhpVdYg/getUpdates "HTTP/1.1 200 OK"
2025-07-07 08:41:14,194 - httpx - INFO - HTTP Request: POST https://api.telegram.org/bot8082065832:AAFMg57PUuHJzTt2YavoqCK5pEBYlhpVdYg/getUpdates "HTTP/1.1 200 OK"
2025-07-07 08:41:24,278 - httpx - INFO - HTTP Request: POST https://api.telegram.org/bot8082065832:AAFMg57PUuHJzTt2YavoqCK5pEBYlhpVdYg/getUpdates "HTTP/1.1 200 OK"
2025-07-07 08:41:34,362 - httpx - INFO - HTTP Request: POST https://api.telegram.org/bot8082065832:AAFMg57PUuHJzTt2YavoqCK5pEBYlhpVdYg/getUpdates "HTTP/1.1 200 OK"
2025-07-07 08:41:44,446 - httpx - INFO - HTTP Request: POST https://api.telegram.org/bot8082065832:AAFMg57PUuHJzTt2YavoqCK5pEBYlhpVdYg/getUpdates "HTTP/1.1 200 OK"
2025-07-07 08:41:54,531 - httpx - INFO - HTTP Request: POST https://api.telegram.org/bot8082065832:AAFMg57PUuHJzTt2YavoqCK5pEBYlhpVdYg/getUpdates "HTTP/1.1 200 OK"
2025-07-07 08:42:04,616 - httpx - INFO - HTTP Request: POST https://api.telegram.org/bot8082065832:AAFMg57PUuHJzTt2YavoqCK5pEBYlhpVdYg/getUpdates "HTTP/1.1 200 OK"
2025-07-07 08:42:14,712 - httpx - INFO - HTTP Request: POST https://api.telegram.org/bot8082065832:AAFMg57PUuHJzTt2YavoqCK5pEBYlhpVdYg/getUpdates "HTTP/1.1 200 OK"
2025-07-07 08:42:24,798 - httpx - INFO - HTTP Request: POST https://api.telegram.org/bot8082065832:AAFMg57PUuHJzTt2YavoqCK5pEBYlhpVdYg/getUpdates "HTTP/1.1 200 OK"
2025-07-07 08:42:34,883 - httpx - INFO - HTTP Request: POST https://api.telegram.org/bot8082065832:AAFMg57PUuHJzTt2YavoqCK5pEBYlhpVdYg/getUpdates "HTTP/1.1 200 OK"
2025-07-07 08:42:44,968 - httpx - INFO - HTTP Request: POST https://api.telegram.org/bot8082065832:AAFMg57PUuHJzTt2YavoqCK5pEBYlhpVdYg/getUpdates "HTTP/1.1 200 OK"
2025-07-07 08:42:55,053 - httpx - INFO - HTTP Request: POST https://api.telegram.org/bot8082065832:AAFMg57PUuHJzTt2YavoqCK5pEBYlhpVdYg/getUpdates "HTTP/1.1 200 OK"
2025-07-07 08:43:05,138 - httpx - INFO - HTTP Request: POST https://api.telegram.org/bot8082065832:AAFMg57PUuHJzTt2YavoqCK5pEBYlhpVdYg/getUpdates "HTTP/1.1 200 OK"
2025-07-07 08:43:15,228 - httpx - INFO - HTTP Request: POST https://api.telegram.org/bot8082065832:AAFMg57PUuHJzTt2YavoqCK5pEBYlhpVdYg/getUpdates "HTTP/1.1 200 OK"
2025-07-07 08:43:25,312 - httpx - INFO - HTTP Request: POST https://api.telegram.org/bot8082065832:AAFMg57PUuHJzTt2YavoqCK5pEBYlhpVdYg/getUpdates "HTTP/1.1 200 OK"
2025-07-07 08:43:35,396 - httpx - INFO - HTTP Request: POST https://api.telegram.org/bot8082065832:AAFMg57PUuHJzTt2YavoqCK5pEBYlhpVdYg/getUpdates "HTTP/1.1 200 OK"
2025-07-07 08:43:45,482 - httpx - INFO - HTTP Request: POST https://api.telegram.org/bot8082065832:AAFMg57PUuHJzTt2YavoqCK5pEBYlhpVdYg/getUpdates "HTTP/1.1 200 OK"
2025-07-07 08:43:55,566 - httpx - INFO - HTTP Request: POST https://api.telegram.org/bot8082065832:AAFMg57PUuHJzTt2YavoqCK5pEBYlhpVdYg/getUpdates "HTTP/1.1 200 OK"
2025-07-07 08:44:05,651 - httpx - INFO - HTTP Request: POST https://api.telegram.org/bot8082065832:AAFMg57PUuHJzTt2YavoqCK5pEBYlhpVdYg/getUpdates "HTTP/1.1 200 OK"
2025-07-07 08:44:15,736 - httpx - INFO - HTTP Request: POST https://api.telegram.org/bot8082065832:AAFMg57PUuHJzTt2YavoqCK5pEBYlhpVdYg/getUpdates "HTTP/1.1 200 OK"
2025-07-07 08:44:25,844 - httpx - INFO - HTTP Request: POST https://api.telegram.org/bot8082065832:AAFMg57PUuHJzTt2YavoqCK5pEBYlhpVdYg/getUpdates "HTTP/1.1 200 OK"
2025-07-07 08:44:35,928 - httpx - INFO - HTTP Request: POST https://api.telegram.org/bot8082065832:AAFMg57PUuHJzTt2YavoqCK5pEBYlhpVdYg/getUpdates "HTTP/1.1 200 OK"
2025-07-07 08:44:46,018 - httpx - INFO - HTTP Request: POST https://api.telegram.org/bot8082065832:AAFMg57PUuHJzTt2YavoqCK5pEBYlhpVdYg/getUpdates "HTTP/1.1 200 OK"
2025-07-07 08:44:56,105 - httpx - INFO - HTTP Request: POST https://api.telegram.org/bot8082065832:AAFMg57PUuHJzTt2YavoqCK5pEBYlhpVdYg/getUpdates "HTTP/1.1 200 OK"
2025-07-07 08:45:06,189 - httpx - INFO - HTTP Request: POST https://api.telegram.org/bot8082065832:AAFMg57PUuHJzTt2YavoqCK5pEBYlhpVdYg/getUpdates "HTTP/1.1 200 OK"
2025-07-07 08:45:16,274 - httpx - INFO - HTTP Request: POST https://api.telegram.org/bot8082065832:AAFMg57PUuHJzTt2YavoqCK5pEBYlhpVdYg/getUpdates "HTTP/1.1 200 OK"
2025-07-07 08:45:26,358 - httpx - INFO - HTTP Request: POST https://api.telegram.org/bot8082065832:AAFMg57PUuHJzTt2YavoqCK5pEBYlhpVdYg/getUpdates "HTTP/1.1 200 OK"
2025-07-07 08:45:36,442 - httpx - INFO - HTTP Request: POST https://api.telegram.org/bot8082065832:AAFMg57PUuHJzTt2YavoqCK5pEBYlhpVdYg/getUpdates "HTTP/1.1 200 OK"
2025-07-07 08:45:46,527 - httpx - INFO - HTTP Request: POST https://api.telegram.org/bot8082065832:AAFMg57PUuHJzTt2YavoqCK5pEBYlhpVdYg/getUpdates "HTTP/1.1 200 OK"
2025-07-07 08:45:56,622 - httpx - INFO - HTTP Request: POST https://api.telegram.org/bot8082065832:AAFMg57PUuHJzTt2YavoqCK5pEBYlhpVdYg/getUpdates "HTTP/1.1 200 OK"
2025-07-07 08:46:06,707 - httpx - INFO - HTTP Request: POST https://api.telegram.org/bot8082065832:AAFMg57PUuHJzTt2YavoqCK5pEBYlhpVdYg/getUpdates "HTTP/1.1 200 OK"
2025-07-07 08:46:16,792 - httpx - INFO - HTTP Request: POST https://api.telegram.org/bot8082065832:AAFMg57PUuHJzTt2YavoqCK5pEBYlhpVdYg/getUpdates "HTTP/1.1 200 OK"
2025-07-07 08:46:26,877 - httpx - INFO - HTTP Request: POST https://api.telegram.org/bot8082065832:AAFMg57PUuHJzTt2YavoqCK5pEBYlhpVdYg/getUpdates "HTTP/1.1 200 OK"
2025-07-07 08:46:36,962 - httpx - INFO - HTTP Request: POST https://api.telegram.org/bot8082065832:AAFMg57PUuHJzTt2YavoqCK5pEBYlhpVdYg/getUpdates "HTTP/1.1 200 OK"
2025-07-07 08:46:47,048 - httpx - INFO - HTTP Request: POST https://api.telegram.org/bot8082065832:AAFMg57PUuHJzTt2YavoqCK5pEBYlhpVdYg/getUpdates "HTTP/1.1 200 OK"
2025-07-07 08:46:57,133 - httpx - INFO - HTTP Request: POST https://api.telegram.org/bot8082065832:AAFMg57PUuHJzTt2YavoqCK5pEBYlhpVdYg/getUpdates "HTTP/1.1 200 OK"
2025-07-07 08:47:07,219 - httpx - INFO - HTTP Request: POST https://api.telegram.org/bot8082065832:AAFMg57PUuHJzTt2YavoqCK5pEBYlhpVdYg/getUpdates "HTTP/1.1 200 OK"
2025-07-07 08:47:17,305 - httpx - INFO - HTTP Request: POST https://api.telegram.org/bot8082065832:AAFMg57PUuHJzTt2YavoqCK5pEBYlhpVdYg/getUpdates "HTTP/1.1 200 OK"
2025-07-07 08:47:27,390 - httpx - INFO - HTTP Request: POST https://api.telegram.org/bot8082065832:AAFMg57PUuHJzTt2YavoqCK5pEBYlhpVdYg/getUpdates "HTTP/1.1 200 OK"
2025-07-07 08:47:37,478 - httpx - INFO - HTTP Request: POST https://api.telegram.org/bot8082065832:AAFMg57PUuHJzTt2YavoqCK5pEBYlhpVdYg/getUpdates "HTTP/1.1 200 OK"
2025-07-07 08:47:47,564 - httpx - INFO - HTTP Request: POST https://api.telegram.org/bot8082065832:AAFMg57PUuHJzTt2YavoqCK5pEBYlhpVdYg/getUpdates "HTTP/1.1 200 OK"
2025-07-07 08:47:57,649 - httpx - INFO - HTTP Request: POST https://api.telegram.org/bot8082065832:AAFMg57PUuHJzTt2YavoqCK5pEBYlhpVdYg/getUpdates "HTTP/1.1 200 OK"
2025-07-07 08:48:07,736 - httpx - INFO - HTTP Request: POST https://api.telegram.org/bot8082065832:AAFMg57PUuHJzTt2YavoqCK5pEBYlhpVdYg/getUpdates "HTTP/1.1 200 OK"
2025-07-07 08:48:17,838 - httpx - INFO - HTTP Request: POST https://api.telegram.org/bot8082065832:AAFMg57PUuHJzTt2YavoqCK5pEBYlhpVdYg/getUpdates "HTTP/1.1 200 OK"
2025-07-07 08:48:27,924 - httpx - INFO - HTTP Request: POST https://api.telegram.org/bot8082065832:AAFMg57PUuHJzTt2YavoqCK5pEBYlhpVdYg/getUpdates "HTTP/1.1 200 OK"
2025-07-07 08:48:37,985 - root - INFO - 🔧 Using Replit-specific entry point
2025-07-07 08:48:37,985 - root - INFO - === QUIZ BOT STARTING ===
2025-07-07 08:48:37,985 - root - INFO - Python version: 3.13.3 (main, Apr  8 2025, 19:55:40) [GCC 14.2.0]
2025-07-07 08:48:37,985 - root - INFO - Environment debug info:
2025-07-07 08:48:37,985 - root - INFO -   Is Replit: False
2025-07-07 08:48:37,985 - root - INFO -   Replit URL: None
2025-07-07 08:48:37,985 - root - INFO - Initializing database...
2025-07-07 08:48:37,986 - root - INFO - Database initialized successfully
2025-07-07 08:48:37,986 - root - INFO - OpenAI API key loaded successfully
2025-07-07 08:48:37,986 - root - INFO - Creating Telegram application...
2025-07-07 08:48:38,011 - httpx - INFO - HTTP Request: POST https://api.telegram.org/bot8082065832:AAFMg57PUuHJzTt2YavoqCK5pEBYlhpVdYg/getUpdates "HTTP/1.1 200 OK"
2025-07-07 08:48:38,034 - root - INFO - Telegram application created successfully
2025-07-07 08:48:38,034 - root - INFO - Registering handlers...
2025-07-07 08:48:38,035 - root - INFO - Handlers registered successfully
2025-07-07 08:48:38,035 - root - INFO - No webhook configured, will use polling mode
2025-07-07 08:48:38,035 - root - INFO - 📡 Starting polling mode...
2025-07-07 08:48:38,294 - httpx - INFO - HTTP Request: POST https://api.telegram.org/bot8082065832:AAFMg57PUuHJzTt2YavoqCK5pEBYlhpVdYg/getMe "HTTP/1.1 200 OK"
2025-07-07 08:48:38,379 - httpx - INFO - HTTP Request: POST https://api.telegram.org/bot8082065832:AAFMg57PUuHJzTt2YavoqCK5pEBYlhpVdYg/deleteWebhook "HTTP/1.1 200 OK"
2025-07-07 08:48:38,379 - telegram.ext.Application - INFO - Application started
2025-07-07 08:48:38,640 - httpx - INFO - HTTP Request: POST https://api.telegram.org/bot8082065832:AAFMg57PUuHJzTt2YavoqCK5pEBYlhpVdYg/getUpdates "HTTP/1.1 409 Conflict"
2025-07-07 08:48:38,641 - telegram.ext.Application - ERROR - No error handlers are registered, logging exception.
Traceback (most recent call last):
  File "/home/ubuntu/.local/lib/python3.13/site-packages/telegram/ext/_utils/networkloop.py", line 115, in network_retry_loop
    if not await do_action():
           ^^^^^^^^^^^^^^^^^
  File "/home/ubuntu/.local/lib/python3.13/site-packages/telegram/ext/_utils/networkloop.py", line 108, in do_action
    return action_cb_task.result()
           ~~~~~~~~~~~~~~~~~~~~~^^
  File "/usr/lib/python3.13/asyncio/futures.py", line 199, in result
    raise self._exception.with_traceback(self._exception_tb)
  File "/usr/lib/python3.13/asyncio/tasks.py", line 304, in __step_run_and_handle_result
    result = coro.send(None)
  File "/home/ubuntu/.local/lib/python3.13/site-packages/telegram/ext/_updater.py", line 340, in polling_action_cb
    updates = await self.bot.get_updates(
              ^^^^^^^^^^^^^^^^^^^^^^^^^^^
    ...<3 lines>...
    )
    ^
  File "/home/ubuntu/.local/lib/python3.13/site-packages/telegram/ext/_extbot.py", line 669, in get_updates
    updates = await super().get_updates(
              ^^^^^^^^^^^^^^^^^^^^^^^^^^
    ...<9 lines>...
    )
    ^
  File "/home/ubuntu/.local/lib/python3.13/site-packages/telegram/_bot.py", line 4610, in get_updates
    await self._post(
    ^^^^^^^^^^^^^^^^^
    ...<7 lines>...
    ),
    ^
  File "/home/ubuntu/.local/lib/python3.13/site-packages/telegram/_bot.py", line 697, in _post
    return await self._do_post(
           ^^^^^^^^^^^^^^^^^^^^
    ...<6 lines>...
    )
    ^
  File "/home/ubuntu/.local/lib/python3.13/site-packages/telegram/ext/_extbot.py", line 369, in _do_post
    return await super()._do_post(
           ^^^^^^^^^^^^^^^^^^^^^^^
    ...<6 lines>...
    )
    ^
  File "/home/ubuntu/.local/lib/python3.13/site-packages/telegram/_bot.py", line 726, in _do_post
    result = await request.post(
             ^^^^^^^^^^^^^^^^^^^
    ...<6 lines>...
    )
    ^
  File "/home/ubuntu/.local/lib/python3.13/site-packages/telegram/request/_baserequest.py", line 197, in post
    result = await self._request_wrapper(
             ^^^^^^^^^^^^^^^^^^^^^^^^^^^^
    ...<7 lines>...
    )
    ^
  File "/home/ubuntu/.local/lib/python3.13/site-packages/telegram/request/_baserequest.py", line 374, in _request_wrapper
    raise exception
telegram.error.Conflict: Conflict: terminated by other getUpdates request; make sure that only one bot instance is running
2025-07-07 08:48:42,728 - httpx - INFO - HTTP Request: POST https://api.telegram.org/bot8082065832:AAFMg57PUuHJzTt2YavoqCK5pEBYlhpVdYg/getUpdates "HTTP/1.1 409 Conflict"
2025-07-07 08:48:42,728 - telegram.ext.Application - ERROR - No error handlers are registered, logging exception.
Traceback (most recent call last):
  File "/home/ubuntu/.local/lib/python3.13/site-packages/telegram/ext/_utils/networkloop.py", line 115, in network_retry_loop
    if not await do_action():
           ^^^^^^^^^^^^^^^^^
  File "/home/ubuntu/.local/lib/python3.13/site-packages/telegram/ext/_utils/networkloop.py", line 108, in do_action
    return action_cb_task.result()
           ~~~~~~~~~~~~~~~~~~~~~^^
  File "/usr/lib/python3.13/asyncio/futures.py", line 199, in result
    raise self._exception.with_traceback(self._exception_tb)
  File "/usr/lib/python3.13/asyncio/tasks.py", line 304, in __step_run_and_handle_result
    result = coro.send(None)
  File "/home/ubuntu/.local/lib/python3.13/site-packages/telegram/ext/_updater.py", line 340, in polling_action_cb
    updates = await self.bot.get_updates(
              ^^^^^^^^^^^^^^^^^^^^^^^^^^^
    ...<3 lines>...
    )
    ^
  File "/home/ubuntu/.local/lib/python3.13/site-packages/telegram/ext/_extbot.py", line 669, in get_updates
    updates = await super().get_updates(
              ^^^^^^^^^^^^^^^^^^^^^^^^^^
    ...<9 lines>...
    )
    ^
  File "/home/ubuntu/.local/lib/python3.13/site-packages/telegram/_bot.py", line 4610, in get_updates
    await self._post(
    ^^^^^^^^^^^^^^^^^
    ...<7 lines>...
    ),
    ^
  File "/home/ubuntu/.local/lib/python3.13/site-packages/telegram/_bot.py", line 697, in _post
    return await self._do_post(
           ^^^^^^^^^^^^^^^^^^^^
    ...<6 lines>...
    )
    ^
  File "/home/ubuntu/.local/lib/python3.13/site-packages/telegram/ext/_extbot.py", line 369, in _do_post
    return await super()._do_post(
           ^^^^^^^^^^^^^^^^^^^^^^^
    ...<6 lines>...
    )
    ^
  File "/home/ubuntu/.local/lib/python3.13/site-packages/telegram/_bot.py", line 726, in _do_post
    result = await request.post(
             ^^^^^^^^^^^^^^^^^^^
    ...<6 lines>...
    )
    ^
  File "/home/ubuntu/.local/lib/python3.13/site-packages/telegram/request/_baserequest.py", line 197, in post
    result = await self._request_wrapper(
             ^^^^^^^^^^^^^^^^^^^^^^^^^^^^
    ...<7 lines>...
    )
    ^
  File "/home/ubuntu/.local/lib/python3.13/site-packages/telegram/request/_baserequest.py", line 374, in _request_wrapper
    raise exception
telegram.error.Conflict: Conflict: terminated by other getUpdates request; make sure that only one bot instance is running
2025-07-07 08:48:43,819 - httpx - INFO - HTTP Request: POST https://api.telegram.org/bot8082065832:AAFMg57PUuHJzTt2YavoqCK5pEBYlhpVdYg/getUpdates "HTTP/1.1 409 Conflict"
2025-07-07 08:48:43,819 - telegram.ext.Application - ERROR - No error handlers are registered, logging exception.
Traceback (most recent call last):
  File "/home/ubuntu/.local/lib/python3.13/site-packages/telegram/ext/_utils/networkloop.py", line 115, in network_retry_loop
    if not await do_action():
           ^^^^^^^^^^^^^^^^^
  File "/home/ubuntu/.local/lib/python3.13/site-packages/telegram/ext/_utils/networkloop.py", line 108, in do_action
    return action_cb_task.result()
           ~~~~~~~~~~~~~~~~~~~~~^^
  File "/usr/lib/python3.13/asyncio/futures.py", line 199, in result
    raise self._exception.with_traceback(self._exception_tb)
  File "/usr/lib/python3.13/asyncio/tasks.py", line 304, in __step_run_and_handle_result
    result = coro.send(None)
  File "/home/ubuntu/.local/lib/python3.13/site-packages/telegram/ext/_updater.py", line 340, in polling_action_cb
    updates = await self.bot.get_updates(
              ^^^^^^^^^^^^^^^^^^^^^^^^^^^
    ...<3 lines>...
    )
    ^
  File "/home/ubuntu/.local/lib/python3.13/site-packages/telegram/ext/_extbot.py", line 669, in get_updates
    updates = await super().get_updates(
              ^^^^^^^^^^^^^^^^^^^^^^^^^^
    ...<9 lines>...
    )
    ^
  File "/home/ubuntu/.local/lib/python3.13/site-packages/telegram/_bot.py", line 4610, in get_updates
    await self._post(
    ^^^^^^^^^^^^^^^^^
    ...<7 lines>...
    ),
    ^
  File "/home/ubuntu/.local/lib/python3.13/site-packages/telegram/_bot.py", line 697, in _post
    return await self._do_post(
           ^^^^^^^^^^^^^^^^^^^^
    ...<6 lines>...
    )
    ^
  File "/home/ubuntu/.local/lib/python3.13/site-packages/telegram/ext/_extbot.py", line 369, in _do_post
    return await super()._do_post(
           ^^^^^^^^^^^^^^^^^^^^^^^
    ...<6 lines>...
    )
    ^
  File "/home/ubuntu/.local/lib/python3.13/site-packages/telegram/_bot.py", line 726, in _do_post
    result = await request.post(
             ^^^^^^^^^^^^^^^^^^^
    ...<6 lines>...
    )
    ^
  File "/home/ubuntu/.local/lib/python3.13/site-packages/telegram/request/_baserequest.py", line 197, in post
    result = await self._request_wrapper(
             ^^^^^^^^^^^^^^^^^^^^^^^^^^^^
    ...<7 lines>...
    )
    ^
  File "/home/ubuntu/.local/lib/python3.13/site-packages/telegram/request/_baserequest.py", line 374, in _request_wrapper
    raise exception
telegram.error.Conflict: Conflict: terminated by other getUpdates request; make sure that only one bot instance is running
2025-07-07 08:48:48,407 - httpx - INFO - HTTP Request: POST https://api.telegram.org/bot8082065832:AAFMg57PUuHJzTt2YavoqCK5pEBYlhpVdYg/getUpdates "HTTP/1.1 409 Conflict"
2025-07-07 08:48:48,408 - telegram.ext.Application - ERROR - No error handlers are registered, logging exception.
Traceback (most recent call last):
  File "/home/ubuntu/.local/lib/python3.13/site-packages/telegram/ext/_utils/networkloop.py", line 115, in network_retry_loop
    if not await do_action():
           ^^^^^^^^^^^^^^^^^
  File "/home/ubuntu/.local/lib/python3.13/site-packages/telegram/ext/_utils/networkloop.py", line 108, in do_action
    return action_cb_task.result()
           ~~~~~~~~~~~~~~~~~~~~~^^
  File "/usr/lib/python3.13/asyncio/futures.py", line 199, in result
    raise self._exception.with_traceback(self._exception_tb)
  File "/usr/lib/python3.13/asyncio/tasks.py", line 304, in __step_run_and_handle_result
    result = coro.send(None)
  File "/home/ubuntu/.local/lib/python3.13/site-packages/telegram/ext/_updater.py", line 340, in polling_action_cb
    updates = await self.bot.get_updates(
              ^^^^^^^^^^^^^^^^^^^^^^^^^^^
    ...<3 lines>...
    )
    ^
  File "/home/ubuntu/.local/lib/python3.13/site-packages/telegram/ext/_extbot.py", line 669, in get_updates
    updates = await super().get_updates(
              ^^^^^^^^^^^^^^^^^^^^^^^^^^
    ...<9 lines>...
    )
    ^
  File "/home/ubuntu/.local/lib/python3.13/site-packages/telegram/_bot.py", line 4610, in get_updates
    await self._post(
    ^^^^^^^^^^^^^^^^^
    ...<7 lines>...
    ),
    ^
  File "/home/ubuntu/.local/lib/python3.13/site-packages/telegram/_bot.py", line 697, in _post
    return await self._do_post(
           ^^^^^^^^^^^^^^^^^^^^
    ...<6 lines>...
    )
    ^
  File "/home/ubuntu/.local/lib/python3.13/site-packages/telegram/ext/_extbot.py", line 369, in _do_post
    return await super()._do_post(
           ^^^^^^^^^^^^^^^^^^^^^^^
    ...<6 lines>...
    )
    ^
  File "/home/ubuntu/.local/lib/python3.13/site-packages/telegram/_bot.py", line 726, in _do_post
    result = await request.post(
             ^^^^^^^^^^^^^^^^^^^
    ...<6 lines>...
    )
    ^
  File "/home/ubuntu/.local/lib/python3.13/site-packages/telegram/request/_baserequest.py", line 197, in post
    result = await self._request_wrapper(
             ^^^^^^^^^^^^^^^^^^^^^^^^^^^^
    ...<7 lines>...
    )
    ^
  File "/home/ubuntu/.local/lib/python3.13/site-packages/telegram/request/_baserequest.py", line 374, in _request_wrapper
    raise exception
telegram.error.Conflict: Conflict: terminated by other getUpdates request; make sure that only one bot instance is running
2025-07-07 08:48:49,998 - httpx - INFO - HTTP Request: POST https://api.telegram.org/bot8082065832:AAFMg57PUuHJzTt2YavoqCK5pEBYlhpVdYg/getUpdates "HTTP/1.1 409 Conflict"
2025-07-07 08:48:49,999 - telegram.ext.Application - ERROR - No error handlers are registered, logging exception.
Traceback (most recent call last):
  File "/home/ubuntu/.local/lib/python3.13/site-packages/telegram/ext/_utils/networkloop.py", line 115, in network_retry_loop
    if not await do_action():
           ^^^^^^^^^^^^^^^^^
  File "/home/ubuntu/.local/lib/python3.13/site-packages/telegram/ext/_utils/networkloop.py", line 108, in do_action
    return action_cb_task.result()
           ~~~~~~~~~~~~~~~~~~~~~^^
  File "/usr/lib/python3.13/asyncio/futures.py", line 199, in result
    raise self._exception.with_traceback(self._exception_tb)
  File "/usr/lib/python3.13/asyncio/tasks.py", line 304, in __step_run_and_handle_result
    result = coro.send(None)
  File "/home/ubuntu/.local/lib/python3.13/site-packages/telegram/ext/_updater.py", line 340, in polling_action_cb
    updates = await self.bot.get_updates(
              ^^^^^^^^^^^^^^^^^^^^^^^^^^^
    ...<3 lines>...
    )
    ^
  File "/home/ubuntu/.local/lib/python3.13/site-packages/telegram/ext/_extbot.py", line 669, in get_updates
    updates = await super().get_updates(
              ^^^^^^^^^^^^^^^^^^^^^^^^^^
    ...<9 lines>...
    )
    ^
  File "/home/ubuntu/.local/lib/python3.13/site-packages/telegram/_bot.py", line 4610, in get_updates
    await self._post(
    ^^^^^^^^^^^^^^^^^
    ...<7 lines>...
    ),
    ^
  File "/home/ubuntu/.local/lib/python3.13/site-packages/telegram/_bot.py", line 697, in _post
    return await self._do_post(
           ^^^^^^^^^^^^^^^^^^^^
    ...<6 lines>...
    )
    ^
  File "/home/ubuntu/.local/lib/python3.13/site-packages/telegram/ext/_extbot.py", line 369, in _do_post
    return await super()._do_post(
           ^^^^^^^^^^^^^^^^^^^^^^^
    ...<6 lines>...
    )
    ^
  File "/home/ubuntu/.local/lib/python3.13/site-packages/telegram/_bot.py", line 726, in _do_post
    result = await request.post(
             ^^^^^^^^^^^^^^^^^^^
    ...<6 lines>...
    )
    ^
  File "/home/ubuntu/.local/lib/python3.13/site-packages/telegram/request/_baserequest.py", line 197, in post
    result = await self._request_wrapper(
             ^^^^^^^^^^^^^^^^^^^^^^^^^^^^
    ...<7 lines>...
    )
    ^
  File "/home/ubuntu/.local/lib/python3.13/site-packages/telegram/request/_baserequest.py", line 374, in _request_wrapper
    raise exception
telegram.error.Conflict: Conflict: terminated by other getUpdates request; make sure that only one bot instance is running
2025-07-07 08:48:55,337 - httpx - INFO - HTTP Request: POST https://api.telegram.org/bot8082065832:AAFMg57PUuHJzTt2YavoqCK5pEBYlhpVdYg/getUpdates "HTTP/1.1 409 Conflict"
2025-07-07 08:48:55,338 - telegram.ext.Application - ERROR - No error handlers are registered, logging exception.
Traceback (most recent call last):
  File "/home/ubuntu/.local/lib/python3.13/site-packages/telegram/ext/_utils/networkloop.py", line 115, in network_retry_loop
    if not await do_action():
           ^^^^^^^^^^^^^^^^^
  File "/home/ubuntu/.local/lib/python3.13/site-packages/telegram/ext/_utils/networkloop.py", line 108, in do_action
    return action_cb_task.result()
           ~~~~~~~~~~~~~~~~~~~~~^^
  File "/usr/lib/python3.13/asyncio/futures.py", line 199, in result
    raise self._exception.with_traceback(self._exception_tb)
  File "/usr/lib/python3.13/asyncio/tasks.py", line 304, in __step_run_and_handle_result
    result = coro.send(None)
  File "/home/ubuntu/.local/lib/python3.13/site-packages/telegram/ext/_updater.py", line 340, in polling_action_cb
    updates = await self.bot.get_updates(
              ^^^^^^^^^^^^^^^^^^^^^^^^^^^
    ...<3 lines>...
    )
    ^
  File "/home/ubuntu/.local/lib/python3.13/site-packages/telegram/ext/_extbot.py", line 669, in get_updates
    updates = await super().get_updates(
              ^^^^^^^^^^^^^^^^^^^^^^^^^^
    ...<9 lines>...
    )
    ^
  File "/home/ubuntu/.local/lib/python3.13/site-packages/telegram/_bot.py", line 4610, in get_updates
    await self._post(
    ^^^^^^^^^^^^^^^^^
    ...<7 lines>...
    ),
    ^
  File "/home/ubuntu/.local/lib/python3.13/site-packages/telegram/_bot.py", line 697, in _post
    return await self._do_post(
           ^^^^^^^^^^^^^^^^^^^^
    ...<6 lines>...
    )
    ^
  File "/home/ubuntu/.local/lib/python3.13/site-packages/telegram/ext/_extbot.py", line 369, in _do_post
    return await super()._do_post(
           ^^^^^^^^^^^^^^^^^^^^^^^
    ...<6 lines>...
    )
    ^
  File "/home/ubuntu/.local/lib/python3.13/site-packages/telegram/_bot.py", line 726, in _do_post
    result = await request.post(
             ^^^^^^^^^^^^^^^^^^^
    ...<6 lines>...
    )
    ^
  File "/home/ubuntu/.local/lib/python3.13/site-packages/telegram/request/_baserequest.py", line 197, in post
    result = await self._request_wrapper(
             ^^^^^^^^^^^^^^^^^^^^^^^^^^^^
    ...<7 lines>...
    )
    ^
  File "/home/ubuntu/.local/lib/python3.13/site-packages/telegram/request/_baserequest.py", line 374, in _request_wrapper
    raise exception
telegram.error.Conflict: Conflict: terminated by other getUpdates request; make sure that only one bot instance is running
2025-07-07 08:48:57,678 - httpx - INFO - HTTP Request: POST https://api.telegram.org/bot8082065832:AAFMg57PUuHJzTt2YavoqCK5pEBYlhpVdYg/getUpdates "HTTP/1.1 409 Conflict"
2025-07-07 08:48:57,678 - telegram.ext.Application - ERROR - No error handlers are registered, logging exception.
Traceback (most recent call last):
  File "/home/ubuntu/.local/lib/python3.13/site-packages/telegram/ext/_utils/networkloop.py", line 115, in network_retry_loop
    if not await do_action():
           ^^^^^^^^^^^^^^^^^
  File "/home/ubuntu/.local/lib/python3.13/site-packages/telegram/ext/_utils/networkloop.py", line 108, in do_action
    return action_cb_task.result()
           ~~~~~~~~~~~~~~~~~~~~~^^
  File "/usr/lib/python3.13/asyncio/futures.py", line 199, in result
    raise self._exception.with_traceback(self._exception_tb)
  File "/usr/lib/python3.13/asyncio/tasks.py", line 304, in __step_run_and_handle_result
    result = coro.send(None)
  File "/home/ubuntu/.local/lib/python3.13/site-packages/telegram/ext/_updater.py", line 340, in polling_action_cb
    updates = await self.bot.get_updates(
              ^^^^^^^^^^^^^^^^^^^^^^^^^^^
    ...<3 lines>...
    )
    ^
  File "/home/ubuntu/.local/lib/python3.13/site-packages/telegram/ext/_extbot.py", line 669, in get_updates
    updates = await super().get_updates(
              ^^^^^^^^^^^^^^^^^^^^^^^^^^
    ...<9 lines>...
    )
    ^
  File "/home/ubuntu/.local/lib/python3.13/site-packages/telegram/_bot.py", line 4610, in get_updates
    await self._post(
    ^^^^^^^^^^^^^^^^^
    ...<7 lines>...
    ),
    ^
  File "/home/ubuntu/.local/lib/python3.13/site-packages/telegram/_bot.py", line 697, in _post
    return await self._do_post(
           ^^^^^^^^^^^^^^^^^^^^
    ...<6 lines>...
    )
    ^
  File "/home/ubuntu/.local/lib/python3.13/site-packages/telegram/ext/_extbot.py", line 369, in _do_post
    return await super()._do_post(
           ^^^^^^^^^^^^^^^^^^^^^^^
    ...<6 lines>...
    )
    ^
  File "/home/ubuntu/.local/lib/python3.13/site-packages/telegram/_bot.py", line 726, in _do_post
    result = await request.post(
             ^^^^^^^^^^^^^^^^^^^
    ...<6 lines>...
    )
    ^
  File "/home/ubuntu/.local/lib/python3.13/site-packages/telegram/request/_baserequest.py", line 197, in post
    result = await self._request_wrapper(
             ^^^^^^^^^^^^^^^^^^^^^^^^^^^^
    ...<7 lines>...
    )
    ^
  File "/home/ubuntu/.local/lib/python3.13/site-packages/telegram/request/_baserequest.py", line 374, in _request_wrapper
    raise exception
telegram.error.Conflict: Conflict: terminated by other getUpdates request; make sure that only one bot instance is running
2025-07-07 08:49:01,142 - httpx - INFO - HTTP Request: POST https://api.telegram.org/bot8082065832:AAFMg57PUuHJzTt2YavoqCK5pEBYlhpVdYg/getUpdates "HTTP/1.1 409 Conflict"
2025-07-07 08:49:01,143 - telegram.ext.Application - ERROR - No error handlers are registered, logging exception.
Traceback (most recent call last):
  File "/home/ubuntu/.local/lib/python3.13/site-packages/telegram/ext/_utils/networkloop.py", line 115, in network_retry_loop
    if not await do_action():
           ^^^^^^^^^^^^^^^^^
  File "/home/ubuntu/.local/lib/python3.13/site-packages/telegram/ext/_utils/networkloop.py", line 108, in do_action
    return action_cb_task.result()
           ~~~~~~~~~~~~~~~~~~~~~^^
  File "/usr/lib/python3.13/asyncio/futures.py", line 199, in result
    raise self._exception.with_traceback(self._exception_tb)
  File "/usr/lib/python3.13/asyncio/tasks.py", line 304, in __step_run_and_handle_result
    result = coro.send(None)
  File "/home/ubuntu/.local/lib/python3.13/site-packages/telegram/ext/_updater.py", line 340, in polling_action_cb
    updates = await self.bot.get_updates(
              ^^^^^^^^^^^^^^^^^^^^^^^^^^^
    ...<3 lines>...
    )
    ^
  File "/home/ubuntu/.local/lib/python3.13/site-packages/telegram/ext/_extbot.py", line 669, in get_updates
    updates = await super().get_updates(
              ^^^^^^^^^^^^^^^^^^^^^^^^^^
    ...<9 lines>...
    )
    ^
  File "/home/ubuntu/.local/lib/python3.13/site-packages/telegram/_bot.py", line 4610, in get_updates
    await self._post(
    ^^^^^^^^^^^^^^^^^
    ...<7 lines>...
    ),
    ^
  File "/home/ubuntu/.local/lib/python3.13/site-packages/telegram/_bot.py", line 697, in _post
    return await self._do_post(
           ^^^^^^^^^^^^^^^^^^^^
    ...<6 lines>...
    )
    ^
  File "/home/ubuntu/.local/lib/python3.13/site-packages/telegram/ext/_extbot.py", line 369, in _do_post
    return await super()._do_post(
           ^^^^^^^^^^^^^^^^^^^^^^^
    ...<6 lines>...
    )
    ^
  File "/home/ubuntu/.local/lib/python3.13/site-packages/telegram/_bot.py", line 726, in _do_post
    result = await request.post(
             ^^^^^^^^^^^^^^^^^^^
    ...<6 lines>...
    )
    ^
  File "/home/ubuntu/.local/lib/python3.13/site-packages/telegram/request/_baserequest.py", line 197, in post
    result = await self._request_wrapper(
             ^^^^^^^^^^^^^^^^^^^^^^^^^^^^
    ...<7 lines>...
    )
    ^
  File "/home/ubuntu/.local/lib/python3.13/site-packages/telegram/request/_baserequest.py", line 374, in _request_wrapper
    raise exception
telegram.error.Conflict: Conflict: terminated by other getUpdates request; make sure that only one bot instance is running
2025-07-07 08:49:04,610 - httpx - INFO - HTTP Request: POST https://api.telegram.org/bot8082065832:AAFMg57PUuHJzTt2YavoqCK5pEBYlhpVdYg/getUpdates "HTTP/1.1 409 Conflict"
2025-07-07 08:49:04,611 - telegram.ext.Application - ERROR - No error handlers are registered, logging exception.
Traceback (most recent call last):
  File "/home/ubuntu/.local/lib/python3.13/site-packages/telegram/ext/_utils/networkloop.py", line 115, in network_retry_loop
    if not await do_action():
           ^^^^^^^^^^^^^^^^^
  File "/home/ubuntu/.local/lib/python3.13/site-packages/telegram/ext/_utils/networkloop.py", line 108, in do_action
    return action_cb_task.result()
           ~~~~~~~~~~~~~~~~~~~~~^^
  File "/usr/lib/python3.13/asyncio/futures.py", line 199, in result
    raise self._exception.with_traceback(self._exception_tb)
  File "/usr/lib/python3.13/asyncio/tasks.py", line 304, in __step_run_and_handle_result
    result = coro.send(None)
  File "/home/ubuntu/.local/lib/python3.13/site-packages/telegram/ext/_updater.py", line 340, in polling_action_cb
    updates = await self.bot.get_updates(
              ^^^^^^^^^^^^^^^^^^^^^^^^^^^
    ...<3 lines>...
    )
    ^
  File "/home/ubuntu/.local/lib/python3.13/site-packages/telegram/ext/_extbot.py", line 669, in get_updates
    updates = await super().get_updates(
              ^^^^^^^^^^^^^^^^^^^^^^^^^^
    ...<9 lines>...
    )
    ^
  File "/home/ubuntu/.local/lib/python3.13/site-packages/telegram/_bot.py", line 4610, in get_updates
    await self._post(
    ^^^^^^^^^^^^^^^^^
    ...<7 lines>...
    ),
    ^
  File "/home/ubuntu/.local/lib/python3.13/site-packages/telegram/_bot.py", line 697, in _post
    return await self._do_post(
           ^^^^^^^^^^^^^^^^^^^^
    ...<6 lines>...
    )
    ^
  File "/home/ubuntu/.local/lib/python3.13/site-packages/telegram/ext/_extbot.py", line 369, in _do_post
    return await super()._do_post(
           ^^^^^^^^^^^^^^^^^^^^^^^
    ...<6 lines>...
    )
    ^
  File "/home/ubuntu/.local/lib/python3.13/site-packages/telegram/_bot.py", line 726, in _do_post
    result = await request.post(
             ^^^^^^^^^^^^^^^^^^^
    ...<6 lines>...
    )
    ^
  File "/home/ubuntu/.local/lib/python3.13/site-packages/telegram/request/_baserequest.py", line 197, in post
    result = await self._request_wrapper(
             ^^^^^^^^^^^^^^^^^^^^^^^^^^^^
    ...<7 lines>...
    )
    ^
  File "/home/ubuntu/.local/lib/python3.13/site-packages/telegram/request/_baserequest.py", line 374, in _request_wrapper
    raise exception
telegram.error.Conflict: Conflict: terminated by other getUpdates request; make sure that only one bot instance is running
2025-07-07 08:49:09,928 - httpx - INFO - HTTP Request: POST https://api.telegram.org/bot8082065832:AAFMg57PUuHJzTt2YavoqCK5pEBYlhpVdYg/getUpdates "HTTP/1.1 409 Conflict"
2025-07-07 08:49:09,929 - telegram.ext.Application - ERROR - No error handlers are registered, logging exception.
Traceback (most recent call last):
  File "/home/ubuntu/.local/lib/python3.13/site-packages/telegram/ext/_utils/networkloop.py", line 115, in network_retry_loop
    if not await do_action():
           ^^^^^^^^^^^^^^^^^
  File "/home/ubuntu/.local/lib/python3.13/site-packages/telegram/ext/_utils/networkloop.py", line 108, in do_action
    return action_cb_task.result()
           ~~~~~~~~~~~~~~~~~~~~~^^
  File "/usr/lib/python3.13/asyncio/futures.py", line 199, in result
    raise self._exception.with_traceback(self._exception_tb)
  File "/usr/lib/python3.13/asyncio/tasks.py", line 304, in __step_run_and_handle_result
    result = coro.send(None)
  File "/home/ubuntu/.local/lib/python3.13/site-packages/telegram/ext/_updater.py", line 340, in polling_action_cb
    updates = await self.bot.get_updates(
              ^^^^^^^^^^^^^^^^^^^^^^^^^^^
    ...<3 lines>...
    )
    ^
  File "/home/ubuntu/.local/lib/python3.13/site-packages/telegram/ext/_extbot.py", line 669, in get_updates
    updates = await super().get_updates(
              ^^^^^^^^^^^^^^^^^^^^^^^^^^
    ...<9 lines>...
    )
    ^
  File "/home/ubuntu/.local/lib/python3.13/site-packages/telegram/_bot.py", line 4610, in get_updates
    await self._post(
    ^^^^^^^^^^^^^^^^^
    ...<7 lines>...
    ),
    ^
  File "/home/ubuntu/.local/lib/python3.13/site-packages/telegram/_bot.py", line 697, in _post
    return await self._do_post(
           ^^^^^^^^^^^^^^^^^^^^
    ...<6 lines>...
    )
    ^
  File "/home/ubuntu/.local/lib/python3.13/site-packages/telegram/ext/_extbot.py", line 369, in _do_post
    return await super()._do_post(
           ^^^^^^^^^^^^^^^^^^^^^^^
    ...<6 lines>...
    )
    ^
  File "/home/ubuntu/.local/lib/python3.13/site-packages/telegram/_bot.py", line 726, in _do_post
    result = await request.post(
             ^^^^^^^^^^^^^^^^^^^
    ...<6 lines>...
    )
    ^
  File "/home/ubuntu/.local/lib/python3.13/site-packages/telegram/request/_baserequest.py", line 197, in post
    result = await self._request_wrapper(
             ^^^^^^^^^^^^^^^^^^^^^^^^^^^^
    ...<7 lines>...
    )
    ^
  File "/home/ubuntu/.local/lib/python3.13/site-packages/telegram/request/_baserequest.py", line 374, in _request_wrapper
    raise exception
telegram.error.Conflict: Conflict: terminated by other getUpdates request; make sure that only one bot instance is running
2025-07-07 08:49:15,249 - httpx - INFO - HTTP Request: POST https://api.telegram.org/bot8082065832:AAFMg57PUuHJzTt2YavoqCK5pEBYlhpVdYg/getUpdates "HTTP/1.1 409 Conflict"
2025-07-07 08:49:15,250 - telegram.ext.Application - ERROR - No error handlers are registered, logging exception.
Traceback (most recent call last):
  File "/home/ubuntu/.local/lib/python3.13/site-packages/telegram/ext/_utils/networkloop.py", line 115, in network_retry_loop
    if not await do_action():
           ^^^^^^^^^^^^^^^^^
  File "/home/ubuntu/.local/lib/python3.13/site-packages/telegram/ext/_utils/networkloop.py", line 108, in do_action
    return action_cb_task.result()
           ~~~~~~~~~~~~~~~~~~~~~^^
  File "/usr/lib/python3.13/asyncio/futures.py", line 199, in result
    raise self._exception.with_traceback(self._exception_tb)
  File "/usr/lib/python3.13/asyncio/tasks.py", line 304, in __step_run_and_handle_result
    result = coro.send(None)
  File "/home/ubuntu/.local/lib/python3.13/site-packages/telegram/ext/_updater.py", line 340, in polling_action_cb
    updates = await self.bot.get_updates(
              ^^^^^^^^^^^^^^^^^^^^^^^^^^^
    ...<3 lines>...
    )
    ^
  File "/home/ubuntu/.local/lib/python3.13/site-packages/telegram/ext/_extbot.py", line 669, in get_updates
    updates = await super().get_updates(
              ^^^^^^^^^^^^^^^^^^^^^^^^^^
    ...<9 lines>...
    )
    ^
  File "/home/ubuntu/.local/lib/python3.13/site-packages/telegram/_bot.py", line 4610, in get_updates
    await self._post(
    ^^^^^^^^^^^^^^^^^
    ...<7 lines>...
    ),
    ^
  File "/home/ubuntu/.local/lib/python3.13/site-packages/telegram/_bot.py", line 697, in _post
    return await self._do_post(
           ^^^^^^^^^^^^^^^^^^^^
    ...<6 lines>...
    )
    ^
  File "/home/ubuntu/.local/lib/python3.13/site-packages/telegram/ext/_extbot.py", line 369, in _do_post
    return await super()._do_post(
           ^^^^^^^^^^^^^^^^^^^^^^^
    ...<6 lines>...
    )
    ^
  File "/home/ubuntu/.local/lib/python3.13/site-packages/telegram/_bot.py", line 726, in _do_post
    result = await request.post(
             ^^^^^^^^^^^^^^^^^^^
    ...<6 lines>...
    )
    ^
  File "/home/ubuntu/.local/lib/python3.13/site-packages/telegram/request/_baserequest.py", line 197, in post
    result = await self._request_wrapper(
             ^^^^^^^^^^^^^^^^^^^^^^^^^^^^
    ...<7 lines>...
    )
    ^
  File "/home/ubuntu/.local/lib/python3.13/site-packages/telegram/request/_baserequest.py", line 374, in _request_wrapper
    raise exception
telegram.error.Conflict: Conflict: terminated by other getUpdates request; make sure that only one bot instance is running
2025-07-07 08:49:23,096 - httpx - INFO - HTTP Request: POST https://api.telegram.org/bot8082065832:AAFMg57PUuHJzTt2YavoqCK5pEBYlhpVdYg/getUpdates "HTTP/1.1 409 Conflict"
2025-07-07 08:49:23,097 - telegram.ext.Application - ERROR - No error handlers are registered, logging exception.
Traceback (most recent call last):
  File "/home/ubuntu/.local/lib/python3.13/site-packages/telegram/ext/_utils/networkloop.py", line 115, in network_retry_loop
    if not await do_action():
           ^^^^^^^^^^^^^^^^^
  File "/home/ubuntu/.local/lib/python3.13/site-packages/telegram/ext/_utils/networkloop.py", line 108, in do_action
    return action_cb_task.result()
           ~~~~~~~~~~~~~~~~~~~~~^^
  File "/usr/lib/python3.13/asyncio/futures.py", line 199, in result
    raise self._exception.with_traceback(self._exception_tb)
  File "/usr/lib/python3.13/asyncio/tasks.py", line 304, in __step_run_and_handle_result
    result = coro.send(None)
  File "/home/ubuntu/.local/lib/python3.13/site-packages/telegram/ext/_updater.py", line 340, in polling_action_cb
    updates = await self.bot.get_updates(
              ^^^^^^^^^^^^^^^^^^^^^^^^^^^
    ...<3 lines>...
    )
    ^
  File "/home/ubuntu/.local/lib/python3.13/site-packages/telegram/ext/_extbot.py", line 669, in get_updates
    updates = await super().get_updates(
              ^^^^^^^^^^^^^^^^^^^^^^^^^^
    ...<9 lines>...
    )
    ^
  File "/home/ubuntu/.local/lib/python3.13/site-packages/telegram/_bot.py", line 4610, in get_updates
    await self._post(
    ^^^^^^^^^^^^^^^^^
    ...<7 lines>...
    ),
    ^
  File "/home/ubuntu/.local/lib/python3.13/site-packages/telegram/_bot.py", line 697, in _post
    return await self._do_post(
           ^^^^^^^^^^^^^^^^^^^^
    ...<6 lines>...
    )
    ^
  File "/home/ubuntu/.local/lib/python3.13/site-packages/telegram/ext/_extbot.py", line 369, in _do_post
    return await super()._do_post(
           ^^^^^^^^^^^^^^^^^^^^^^^
    ...<6 lines>...
    )
    ^
  File "/home/ubuntu/.local/lib/python3.13/site-packages/telegram/_bot.py", line 726, in _do_post
    result = await request.post(
             ^^^^^^^^^^^^^^^^^^^
    ...<6 lines>...
    )
    ^
  File "/home/ubuntu/.local/lib/python3.13/site-packages/telegram/request/_baserequest.py", line 197, in post
    result = await self._request_wrapper(
             ^^^^^^^^^^^^^^^^^^^^^^^^^^^^
    ...<7 lines>...
    )
    ^
  File "/home/ubuntu/.local/lib/python3.13/site-packages/telegram/request/_baserequest.py", line 374, in _request_wrapper
    raise exception
telegram.error.Conflict: Conflict: terminated by other getUpdates request; make sure that only one bot instance is running
2025-07-07 08:49:30,969 - httpx - INFO - HTTP Request: POST https://api.telegram.org/bot8082065832:AAFMg57PUuHJzTt2YavoqCK5pEBYlhpVdYg/getUpdates "HTTP/1.1 409 Conflict"
2025-07-07 08:49:30,970 - telegram.ext.Application - ERROR - No error handlers are registered, logging exception.
Traceback (most recent call last):
  File "/home/ubuntu/.local/lib/python3.13/site-packages/telegram/ext/_utils/networkloop.py", line 115, in network_retry_loop
    if not await do_action():
           ^^^^^^^^^^^^^^^^^
  File "/home/ubuntu/.local/lib/python3.13/site-packages/telegram/ext/_utils/networkloop.py", line 108, in do_action
    return action_cb_task.result()
           ~~~~~~~~~~~~~~~~~~~~~^^
  File "/usr/lib/python3.13/asyncio/futures.py", line 199, in result
    raise self._exception.with_traceback(self._exception_tb)
  File "/usr/lib/python3.13/asyncio/tasks.py", line 304, in __step_run_and_handle_result
    result = coro.send(None)
  File "/home/ubuntu/.local/lib/python3.13/site-packages/telegram/ext/_updater.py", line 340, in polling_action_cb
    updates = await self.bot.get_updates(
              ^^^^^^^^^^^^^^^^^^^^^^^^^^^
    ...<3 lines>...
    )
    ^
  File "/home/ubuntu/.local/lib/python3.13/site-packages/telegram/ext/_extbot.py", line 669, in get_updates
    updates = await super().get_updates(
              ^^^^^^^^^^^^^^^^^^^^^^^^^^
    ...<9 lines>...
    )
    ^
  File "/home/ubuntu/.local/lib/python3.13/site-packages/telegram/_bot.py", line 4610, in get_updates
    await self._post(
    ^^^^^^^^^^^^^^^^^
    ...<7 lines>...
    ),
    ^
  File "/home/ubuntu/.local/lib/python3.13/site-packages/telegram/_bot.py", line 697, in _post
    return await self._do_post(
           ^^^^^^^^^^^^^^^^^^^^
    ...<6 lines>...
    )
    ^
  File "/home/ubuntu/.local/lib/python3.13/site-packages/telegram/ext/_extbot.py", line 369, in _do_post
    return await super()._do_post(
           ^^^^^^^^^^^^^^^^^^^^^^^
    ...<6 lines>...
    )
    ^
  File "/home/ubuntu/.local/lib/python3.13/site-packages/telegram/_bot.py", line 726, in _do_post
    result = await request.post(
             ^^^^^^^^^^^^^^^^^^^
    ...<6 lines>...
    )
    ^
  File "/home/ubuntu/.local/lib/python3.13/site-packages/telegram/request/_baserequest.py", line 197, in post
    result = await self._request_wrapper(
             ^^^^^^^^^^^^^^^^^^^^^^^^^^^^
    ...<7 lines>...
    )
    ^
  File "/home/ubuntu/.local/lib/python3.13/site-packages/telegram/request/_baserequest.py", line 374, in _request_wrapper
    raise exception
telegram.error.Conflict: Conflict: terminated by other getUpdates request; make sure that only one bot instance is running
2025-07-07 08:49:40,969 - httpx - INFO - HTTP Request: POST https://api.telegram.org/bot8082065832:AAFMg57PUuHJzTt2YavoqCK5pEBYlhpVdYg/getUpdates "HTTP/1.1 200 OK"
2025-07-07 08:49:42,627 - httpx - INFO - HTTP Request: POST https://api.telegram.org/bot8082065832:AAFMg57PUuHJzTt2YavoqCK5pEBYlhpVdYg/getUpdates "HTTP/1.1 409 Conflict"
2025-07-07 08:49:42,628 - telegram.ext.Application - ERROR - No error handlers are registered, logging exception.
Traceback (most recent call last):
  File "/home/ubuntu/.local/lib/python3.13/site-packages/telegram/ext/_utils/networkloop.py", line 115, in network_retry_loop
    if not await do_action():
           ^^^^^^^^^^^^^^^^^
  File "/home/ubuntu/.local/lib/python3.13/site-packages/telegram/ext/_utils/networkloop.py", line 108, in do_action
    return action_cb_task.result()
           ~~~~~~~~~~~~~~~~~~~~~^^
  File "/usr/lib/python3.13/asyncio/futures.py", line 199, in result
    raise self._exception.with_traceback(self._exception_tb)
  File "/usr/lib/python3.13/asyncio/tasks.py", line 304, in __step_run_and_handle_result
    result = coro.send(None)
  File "/home/ubuntu/.local/lib/python3.13/site-packages/telegram/ext/_updater.py", line 340, in polling_action_cb
    updates = await self.bot.get_updates(
              ^^^^^^^^^^^^^^^^^^^^^^^^^^^
    ...<3 lines>...
    )
    ^
  File "/home/ubuntu/.local/lib/python3.13/site-packages/telegram/ext/_extbot.py", line 669, in get_updates
    updates = await super().get_updates(
              ^^^^^^^^^^^^^^^^^^^^^^^^^^
    ...<9 lines>...
    )
    ^
  File "/home/ubuntu/.local/lib/python3.13/site-packages/telegram/_bot.py", line 4610, in get_updates
    await self._post(
    ^^^^^^^^^^^^^^^^^
    ...<7 lines>...
    ),
    ^
  File "/home/ubuntu/.local/lib/python3.13/site-packages/telegram/_bot.py", line 697, in _post
    return await self._do_post(
           ^^^^^^^^^^^^^^^^^^^^
    ...<6 lines>...
    )
    ^
  File "/home/ubuntu/.local/lib/python3.13/site-packages/telegram/ext/_extbot.py", line 369, in _do_post
    return await super()._do_post(
           ^^^^^^^^^^^^^^^^^^^^^^^
    ...<6 lines>...
    )
    ^
  File "/home/ubuntu/.local/lib/python3.13/site-packages/telegram/_bot.py", line 726, in _do_post
    result = await request.post(
             ^^^^^^^^^^^^^^^^^^^
    ...<6 lines>...
    )
    ^
  File "/home/ubuntu/.local/lib/python3.13/site-packages/telegram/request/_baserequest.py", line 197, in post
    result = await self._request_wrapper(
             ^^^^^^^^^^^^^^^^^^^^^^^^^^^^
    ...<7 lines>...
    )
    ^
  File "/home/ubuntu/.local/lib/python3.13/site-packages/telegram/request/_baserequest.py", line 374, in _request_wrapper
    raise exception
telegram.error.Conflict: Conflict: terminated by other getUpdates request; make sure that only one bot instance is running
2025-07-07 08:49:46,719 - httpx - INFO - HTTP Request: POST https://api.telegram.org/bot8082065832:AAFMg57PUuHJzTt2YavoqCK5pEBYlhpVdYg/getUpdates "HTTP/1.1 409 Conflict"
2025-07-07 08:49:46,720 - telegram.ext.Application - ERROR - No error handlers are registered, logging exception.
Traceback (most recent call last):
  File "/home/ubuntu/.local/lib/python3.13/site-packages/telegram/ext/_utils/networkloop.py", line 115, in network_retry_loop
    if not await do_action():
           ^^^^^^^^^^^^^^^^^
  File "/home/ubuntu/.local/lib/python3.13/site-packages/telegram/ext/_utils/networkloop.py", line 108, in do_action
    return action_cb_task.result()
           ~~~~~~~~~~~~~~~~~~~~~^^
  File "/usr/lib/python3.13/asyncio/futures.py", line 199, in result
    raise self._exception.with_traceback(self._exception_tb)
  File "/usr/lib/python3.13/asyncio/tasks.py", line 304, in __step_run_and_handle_result
    result = coro.send(None)
  File "/home/ubuntu/.local/lib/python3.13/site-packages/telegram/ext/_updater.py", line 340, in polling_action_cb
    updates = await self.bot.get_updates(
              ^^^^^^^^^^^^^^^^^^^^^^^^^^^
    ...<3 lines>...
    )
    ^
  File "/home/ubuntu/.local/lib/python3.13/site-packages/telegram/ext/_extbot.py", line 669, in get_updates
    updates = await super().get_updates(
              ^^^^^^^^^^^^^^^^^^^^^^^^^^
    ...<9 lines>...
    )
    ^
  File "/home/ubuntu/.local/lib/python3.13/site-packages/telegram/_bot.py", line 4610, in get_updates
    await self._post(
    ^^^^^^^^^^^^^^^^^
    ...<7 lines>...
    ),
    ^
  File "/home/ubuntu/.local/lib/python3.13/site-packages/telegram/_bot.py", line 697, in _post
    return await self._do_post(
           ^^^^^^^^^^^^^^^^^^^^
    ...<6 lines>...
    )
    ^
  File "/home/ubuntu/.local/lib/python3.13/site-packages/telegram/ext/_extbot.py", line 369, in _do_post
    return await super()._do_post(
           ^^^^^^^^^^^^^^^^^^^^^^^
    ...<6 lines>...
    )
    ^
  File "/home/ubuntu/.local/lib/python3.13/site-packages/telegram/_bot.py", line 726, in _do_post
    result = await request.post(
             ^^^^^^^^^^^^^^^^^^^
    ...<6 lines>...
    )
    ^
  File "/home/ubuntu/.local/lib/python3.13/site-packages/telegram/request/_baserequest.py", line 197, in post
    result = await self._request_wrapper(
             ^^^^^^^^^^^^^^^^^^^^^^^^^^^^
    ...<7 lines>...
    )
    ^
  File "/home/ubuntu/.local/lib/python3.13/site-packages/telegram/request/_baserequest.py", line 374, in _request_wrapper
    raise exception
telegram.error.Conflict: Conflict: terminated by other getUpdates request; make sure that only one bot instance is running
2025-07-07 08:49:53,719 - httpx - INFO - HTTP Request: POST https://api.telegram.org/bot8082065832:AAFMg57PUuHJzTt2YavoqCK5pEBYlhpVdYg/getUpdates "HTTP/1.1 200 OK"
2025-07-07 08:50:03,813 - httpx - INFO - HTTP Request: POST https://api.telegram.org/bot8082065832:AAFMg57PUuHJzTt2YavoqCK5pEBYlhpVdYg/getUpdates "HTTP/1.1 200 OK"
2025-07-07 08:50:04,082 - httpx - INFO - HTTP Request: POST https://api.telegram.org/bot8082065832:AAFMg57PUuHJzTt2YavoqCK5pEBYlhpVdYg/getUpdates "HTTP/1.1 409 Conflict"
2025-07-07 08:50:04,082 - telegram.ext.Application - ERROR - No error handlers are registered, logging exception.
Traceback (most recent call last):
  File "/home/ubuntu/.local/lib/python3.13/site-packages/telegram/ext/_utils/networkloop.py", line 115, in network_retry_loop
    if not await do_action():
           ^^^^^^^^^^^^^^^^^
  File "/home/ubuntu/.local/lib/python3.13/site-packages/telegram/ext/_utils/networkloop.py", line 108, in do_action
    return action_cb_task.result()
           ~~~~~~~~~~~~~~~~~~~~~^^
  File "/usr/lib/python3.13/asyncio/futures.py", line 199, in result
    raise self._exception.with_traceback(self._exception_tb)
  File "/usr/lib/python3.13/asyncio/tasks.py", line 304, in __step_run_and_handle_result
    result = coro.send(None)
  File "/home/ubuntu/.local/lib/python3.13/site-packages/telegram/ext/_updater.py", line 340, in polling_action_cb
    updates = await self.bot.get_updates(
              ^^^^^^^^^^^^^^^^^^^^^^^^^^^
    ...<3 lines>...
    )
    ^
  File "/home/ubuntu/.local/lib/python3.13/site-packages/telegram/ext/_extbot.py", line 669, in get_updates
    updates = await super().get_updates(
              ^^^^^^^^^^^^^^^^^^^^^^^^^^
    ...<9 lines>...
    )
    ^
  File "/home/ubuntu/.local/lib/python3.13/site-packages/telegram/_bot.py", line 4610, in get_updates
    await self._post(
    ^^^^^^^^^^^^^^^^^
    ...<7 lines>...
    ),
    ^
  File "/home/ubuntu/.local/lib/python3.13/site-packages/telegram/_bot.py", line 697, in _post
    return await self._do_post(
           ^^^^^^^^^^^^^^^^^^^^
    ...<6 lines>...
    )
    ^
  File "/home/ubuntu/.local/lib/python3.13/site-packages/telegram/ext/_extbot.py", line 369, in _do_post
    return await super()._do_post(
           ^^^^^^^^^^^^^^^^^^^^^^^
    ...<6 lines>...
    )
    ^
  File "/home/ubuntu/.local/lib/python3.13/site-packages/telegram/_bot.py", line 726, in _do_post
    result = await request.post(
             ^^^^^^^^^^^^^^^^^^^
    ...<6 lines>...
    )
    ^
  File "/home/ubuntu/.local/lib/python3.13/site-packages/telegram/request/_baserequest.py", line 197, in post
    result = await self._request_wrapper(
             ^^^^^^^^^^^^^^^^^^^^^^^^^^^^
    ...<7 lines>...
    )
    ^
  File "/home/ubuntu/.local/lib/python3.13/site-packages/telegram/request/_baserequest.py", line 374, in _request_wrapper
    raise exception
telegram.error.Conflict: Conflict: terminated by other getUpdates request; make sure that only one bot instance is running
2025-07-07 08:50:08,184 - httpx - INFO - HTTP Request: POST https://api.telegram.org/bot8082065832:AAFMg57PUuHJzTt2YavoqCK5pEBYlhpVdYg/getUpdates "HTTP/1.1 409 Conflict"
2025-07-07 08:50:08,184 - telegram.ext.Application - ERROR - No error handlers are registered, logging exception.
Traceback (most recent call last):
  File "/home/ubuntu/.local/lib/python3.13/site-packages/telegram/ext/_utils/networkloop.py", line 115, in network_retry_loop
    if not await do_action():
           ^^^^^^^^^^^^^^^^^
  File "/home/ubuntu/.local/lib/python3.13/site-packages/telegram/ext/_utils/networkloop.py", line 108, in do_action
    return action_cb_task.result()
           ~~~~~~~~~~~~~~~~~~~~~^^
  File "/usr/lib/python3.13/asyncio/futures.py", line 199, in result
    raise self._exception.with_traceback(self._exception_tb)
  File "/usr/lib/python3.13/asyncio/tasks.py", line 304, in __step_run_and_handle_result
    result = coro.send(None)
  File "/home/ubuntu/.local/lib/python3.13/site-packages/telegram/ext/_updater.py", line 340, in polling_action_cb
    updates = await self.bot.get_updates(
              ^^^^^^^^^^^^^^^^^^^^^^^^^^^
    ...<3 lines>...
    )
    ^
  File "/home/ubuntu/.local/lib/python3.13/site-packages/telegram/ext/_extbot.py", line 669, in get_updates
    updates = await super().get_updates(
              ^^^^^^^^^^^^^^^^^^^^^^^^^^
    ...<9 lines>...
    )
    ^
  File "/home/ubuntu/.local/lib/python3.13/site-packages/telegram/_bot.py", line 4610, in get_updates
    await self._post(
    ^^^^^^^^^^^^^^^^^
    ...<7 lines>...
    ),
    ^
  File "/home/ubuntu/.local/lib/python3.13/site-packages/telegram/_bot.py", line 697, in _post
    return await self._do_post(
           ^^^^^^^^^^^^^^^^^^^^
    ...<6 lines>...
    )
    ^
  File "/home/ubuntu/.local/lib/python3.13/site-packages/telegram/ext/_extbot.py", line 369, in _do_post
    return await super()._do_post(
           ^^^^^^^^^^^^^^^^^^^^^^^
    ...<6 lines>...
    )
    ^
  File "/home/ubuntu/.local/lib/python3.13/site-packages/telegram/_bot.py", line 726, in _do_post
    result = await request.post(
             ^^^^^^^^^^^^^^^^^^^
    ...<6 lines>...
    )
    ^
  File "/home/ubuntu/.local/lib/python3.13/site-packages/telegram/request/_baserequest.py", line 197, in post
    result = await self._request_wrapper(
             ^^^^^^^^^^^^^^^^^^^^^^^^^^^^
    ...<7 lines>...
    )
    ^
  File "/home/ubuntu/.local/lib/python3.13/site-packages/telegram/request/_baserequest.py", line 374, in _request_wrapper
    raise exception
telegram.error.Conflict: Conflict: terminated by other getUpdates request; make sure that only one bot instance is running
2025-07-07 08:50:15,178 - httpx - INFO - HTTP Request: POST https://api.telegram.org/bot8082065832:AAFMg57PUuHJzTt2YavoqCK5pEBYlhpVdYg/getUpdates "HTTP/1.1 200 OK"
2025-07-07 08:50:25,271 - httpx - INFO - HTTP Request: POST https://api.telegram.org/bot8082065832:AAFMg57PUuHJzTt2YavoqCK5pEBYlhpVdYg/getUpdates "HTTP/1.1 200 OK"
2025-07-07 08:50:34,086 - httpx - INFO - HTTP Request: POST https://api.telegram.org/bot8082065832:AAFMg57PUuHJzTt2YavoqCK5pEBYlhpVdYg/getUpdates "HTTP/1.1 409 Conflict"
2025-07-07 08:50:34,087 - telegram.ext.Application - ERROR - No error handlers are registered, logging exception.
Traceback (most recent call last):
  File "/home/ubuntu/.local/lib/python3.13/site-packages/telegram/ext/_utils/networkloop.py", line 115, in network_retry_loop
    if not await do_action():
           ^^^^^^^^^^^^^^^^^
  File "/home/ubuntu/.local/lib/python3.13/site-packages/telegram/ext/_utils/networkloop.py", line 108, in do_action
    return action_cb_task.result()
           ~~~~~~~~~~~~~~~~~~~~~^^
  File "/usr/lib/python3.13/asyncio/futures.py", line 199, in result
    raise self._exception.with_traceback(self._exception_tb)
  File "/usr/lib/python3.13/asyncio/tasks.py", line 304, in __step_run_and_handle_result
    result = coro.send(None)
  File "/home/ubuntu/.local/lib/python3.13/site-packages/telegram/ext/_updater.py", line 340, in polling_action_cb
    updates = await self.bot.get_updates(
              ^^^^^^^^^^^^^^^^^^^^^^^^^^^
    ...<3 lines>...
    )
    ^
  File "/home/ubuntu/.local/lib/python3.13/site-packages/telegram/ext/_extbot.py", line 669, in get_updates
    updates = await super().get_updates(
              ^^^^^^^^^^^^^^^^^^^^^^^^^^
    ...<9 lines>...
    )
    ^
  File "/home/ubuntu/.local/lib/python3.13/site-packages/telegram/_bot.py", line 4610, in get_updates
    await self._post(
    ^^^^^^^^^^^^^^^^^
    ...<7 lines>...
    ),
    ^
  File "/home/ubuntu/.local/lib/python3.13/site-packages/telegram/_bot.py", line 697, in _post
    return await self._do_post(
           ^^^^^^^^^^^^^^^^^^^^
    ...<6 lines>...
    )
    ^
  File "/home/ubuntu/.local/lib/python3.13/site-packages/telegram/ext/_extbot.py", line 369, in _do_post
    return await super()._do_post(
           ^^^^^^^^^^^^^^^^^^^^^^^
    ...<6 lines>...
    )
    ^
  File "/home/ubuntu/.local/lib/python3.13/site-packages/telegram/_bot.py", line 726, in _do_post
    result = await request.post(
             ^^^^^^^^^^^^^^^^^^^
    ...<6 lines>...
    )
    ^
  File "/home/ubuntu/.local/lib/python3.13/site-packages/telegram/request/_baserequest.py", line 197, in post
    result = await self._request_wrapper(
             ^^^^^^^^^^^^^^^^^^^^^^^^^^^^
    ...<7 lines>...
    )
    ^
  File "/home/ubuntu/.local/lib/python3.13/site-packages/telegram/request/_baserequest.py", line 374, in _request_wrapper
    raise exception
telegram.error.Conflict: Conflict: terminated by other getUpdates request; make sure that only one bot instance is running
2025-07-07 08:50:38,179 - httpx - INFO - HTTP Request: POST https://api.telegram.org/bot8082065832:AAFMg57PUuHJzTt2YavoqCK5pEBYlhpVdYg/getUpdates "HTTP/1.1 409 Conflict"
2025-07-07 08:50:38,179 - telegram.ext.Application - ERROR - No error handlers are registered, logging exception.
Traceback (most recent call last):
  File "/home/ubuntu/.local/lib/python3.13/site-packages/telegram/ext/_utils/networkloop.py", line 115, in network_retry_loop
    if not await do_action():
           ^^^^^^^^^^^^^^^^^
  File "/home/ubuntu/.local/lib/python3.13/site-packages/telegram/ext/_utils/networkloop.py", line 108, in do_action
    return action_cb_task.result()
           ~~~~~~~~~~~~~~~~~~~~~^^
  File "/usr/lib/python3.13/asyncio/futures.py", line 199, in result
    raise self._exception.with_traceback(self._exception_tb)
  File "/usr/lib/python3.13/asyncio/tasks.py", line 304, in __step_run_and_handle_result
    result = coro.send(None)
  File "/home/ubuntu/.local/lib/python3.13/site-packages/telegram/ext/_updater.py", line 340, in polling_action_cb
    updates = await self.bot.get_updates(
              ^^^^^^^^^^^^^^^^^^^^^^^^^^^
    ...<3 lines>...
    )
    ^
  File "/home/ubuntu/.local/lib/python3.13/site-packages/telegram/ext/_extbot.py", line 669, in get_updates
    updates = await super().get_updates(
              ^^^^^^^^^^^^^^^^^^^^^^^^^^
    ...<9 lines>...
    )
    ^
  File "/home/ubuntu/.local/lib/python3.13/site-packages/telegram/_bot.py", line 4610, in get_updates
    await self._post(
    ^^^^^^^^^^^^^^^^^
    ...<7 lines>...
    ),
    ^
  File "/home/ubuntu/.local/lib/python3.13/site-packages/telegram/_bot.py", line 697, in _post
    return await self._do_post(
           ^^^^^^^^^^^^^^^^^^^^
    ...<6 lines>...
    )
    ^
  File "/home/ubuntu/.local/lib/python3.13/site-packages/telegram/ext/_extbot.py", line 369, in _do_post
    return await super()._do_post(
           ^^^^^^^^^^^^^^^^^^^^^^^
    ...<6 lines>...
    )
    ^
  File "/home/ubuntu/.local/lib/python3.13/site-packages/telegram/_bot.py", line 726, in _do_post
    result = await request.post(
             ^^^^^^^^^^^^^^^^^^^
    ...<6 lines>...
    )
    ^
  File "/home/ubuntu/.local/lib/python3.13/site-packages/telegram/request/_baserequest.py", line 197, in post
    result = await self._request_wrapper(
             ^^^^^^^^^^^^^^^^^^^^^^^^^^^^
    ...<7 lines>...
    )
    ^
  File "/home/ubuntu/.local/lib/python3.13/site-packages/telegram/request/_baserequest.py", line 374, in _request_wrapper
    raise exception
telegram.error.Conflict: Conflict: terminated by other getUpdates request; make sure that only one bot instance is running
2025-07-07 08:50:45,178 - httpx - INFO - HTTP Request: POST https://api.telegram.org/bot8082065832:AAFMg57PUuHJzTt2YavoqCK5pEBYlhpVdYg/getUpdates "HTTP/1.1 200 OK"
2025-07-07 08:50:55,268 - httpx - INFO - HTTP Request: POST https://api.telegram.org/bot8082065832:AAFMg57PUuHJzTt2YavoqCK5pEBYlhpVdYg/getUpdates "HTTP/1.1 200 OK"
2025-07-07 08:51:05,358 - httpx - INFO - HTTP Request: POST https://api.telegram.org/bot8082065832:AAFMg57PUuHJzTt2YavoqCK5pEBYlhpVdYg/getUpdates "HTTP/1.1 200 OK"
2025-07-07 08:51:08,464 - httpx - INFO - HTTP Request: POST https://api.telegram.org/bot8082065832:AAFMg57PUuHJzTt2YavoqCK5pEBYlhpVdYg/getUpdates "HTTP/1.1 409 Conflict"
2025-07-07 08:51:08,464 - telegram.ext.Application - ERROR - No error handlers are registered, logging exception.
Traceback (most recent call last):
  File "/home/ubuntu/.local/lib/python3.13/site-packages/telegram/ext/_utils/networkloop.py", line 115, in network_retry_loop
    if not await do_action():
           ^^^^^^^^^^^^^^^^^
  File "/home/ubuntu/.local/lib/python3.13/site-packages/telegram/ext/_utils/networkloop.py", line 108, in do_action
    return action_cb_task.result()
           ~~~~~~~~~~~~~~~~~~~~~^^
  File "/usr/lib/python3.13/asyncio/futures.py", line 199, in result
    raise self._exception.with_traceback(self._exception_tb)
  File "/usr/lib/python3.13/asyncio/tasks.py", line 304, in __step_run_and_handle_result
    result = coro.send(None)
  File "/home/ubuntu/.local/lib/python3.13/site-packages/telegram/ext/_updater.py", line 340, in polling_action_cb
    updates = await self.bot.get_updates(
              ^^^^^^^^^^^^^^^^^^^^^^^^^^^
    ...<3 lines>...
    )
    ^
  File "/home/ubuntu/.local/lib/python3.13/site-packages/telegram/ext/_extbot.py", line 669, in get_updates
    updates = await super().get_updates(
              ^^^^^^^^^^^^^^^^^^^^^^^^^^
    ...<9 lines>...
    )
    ^
  File "/home/ubuntu/.local/lib/python3.13/site-packages/telegram/_bot.py", line 4610, in get_updates
    await self._post(
    ^^^^^^^^^^^^^^^^^
    ...<7 lines>...
    ),
    ^
  File "/home/ubuntu/.local/lib/python3.13/site-packages/telegram/_bot.py", line 697, in _post
    return await self._do_post(
           ^^^^^^^^^^^^^^^^^^^^
    ...<6 lines>...
    )
    ^
  File "/home/ubuntu/.local/lib/python3.13/site-packages/telegram/ext/_extbot.py", line 369, in _do_post
    return await super()._do_post(
           ^^^^^^^^^^^^^^^^^^^^^^^
    ...<6 lines>...
    )
    ^
  File "/home/ubuntu/.local/lib/python3.13/site-packages/telegram/_bot.py", line 726, in _do_post
    result = await request.post(
             ^^^^^^^^^^^^^^^^^^^
    ...<6 lines>...
    )
    ^
  File "/home/ubuntu/.local/lib/python3.13/site-packages/telegram/request/_baserequest.py", line 197, in post
    result = await self._request_wrapper(
             ^^^^^^^^^^^^^^^^^^^^^^^^^^^^
    ...<7 lines>...
    )
    ^
  File "/home/ubuntu/.local/lib/python3.13/site-packages/telegram/request/_baserequest.py", line 374, in _request_wrapper
    raise exception
telegram.error.Conflict: Conflict: terminated by other getUpdates request; make sure that only one bot instance is running
2025-07-07 08:51:12,556 - httpx - INFO - HTTP Request: POST https://api.telegram.org/bot8082065832:AAFMg57PUuHJzTt2YavoqCK5pEBYlhpVdYg/getUpdates "HTTP/1.1 409 Conflict"
2025-07-07 08:51:12,557 - telegram.ext.Application - ERROR - No error handlers are registered, logging exception.
Traceback (most recent call last):
  File "/home/ubuntu/.local/lib/python3.13/site-packages/telegram/ext/_utils/networkloop.py", line 115, in network_retry_loop
    if not await do_action():
           ^^^^^^^^^^^^^^^^^
  File "/home/ubuntu/.local/lib/python3.13/site-packages/telegram/ext/_utils/networkloop.py", line 108, in do_action
    return action_cb_task.result()
           ~~~~~~~~~~~~~~~~~~~~~^^
  File "/usr/lib/python3.13/asyncio/futures.py", line 199, in result
    raise self._exception.with_traceback(self._exception_tb)
  File "/usr/lib/python3.13/asyncio/tasks.py", line 304, in __step_run_and_handle_result
    result = coro.send(None)
  File "/home/ubuntu/.local/lib/python3.13/site-packages/telegram/ext/_updater.py", line 340, in polling_action_cb
    updates = await self.bot.get_updates(
              ^^^^^^^^^^^^^^^^^^^^^^^^^^^
    ...<3 lines>...
    )
    ^
  File "/home/ubuntu/.local/lib/python3.13/site-packages/telegram/ext/_extbot.py", line 669, in get_updates
    updates = await super().get_updates(
              ^^^^^^^^^^^^^^^^^^^^^^^^^^
    ...<9 lines>...
    )
    ^
  File "/home/ubuntu/.local/lib/python3.13/site-packages/telegram/_bot.py", line 4610, in get_updates
    await self._post(
    ^^^^^^^^^^^^^^^^^
    ...<7 lines>...
    ),
    ^
  File "/home/ubuntu/.local/lib/python3.13/site-packages/telegram/_bot.py", line 697, in _post
    return await self._do_post(
           ^^^^^^^^^^^^^^^^^^^^
    ...<6 lines>...
    )
    ^
  File "/home/ubuntu/.local/lib/python3.13/site-packages/telegram/ext/_extbot.py", line 369, in _do_post
    return await super()._do_post(
           ^^^^^^^^^^^^^^^^^^^^^^^
    ...<6 lines>...
    )
    ^
  File "/home/ubuntu/.local/lib/python3.13/site-packages/telegram/_bot.py", line 726, in _do_post
    result = await request.post(
             ^^^^^^^^^^^^^^^^^^^
    ...<6 lines>...
    )
    ^
  File "/home/ubuntu/.local/lib/python3.13/site-packages/telegram/request/_baserequest.py", line 197, in post
    result = await self._request_wrapper(
             ^^^^^^^^^^^^^^^^^^^^^^^^^^^^
    ...<7 lines>...
    )
    ^
  File "/home/ubuntu/.local/lib/python3.13/site-packages/telegram/request/_baserequest.py", line 374, in _request_wrapper
    raise exception
telegram.error.Conflict: Conflict: terminated by other getUpdates request; make sure that only one bot instance is running
2025-07-07 08:51:19,555 - httpx - INFO - HTTP Request: POST https://api.telegram.org/bot8082065832:AAFMg57PUuHJzTt2YavoqCK5pEBYlhpVdYg/getUpdates "HTTP/1.1 200 OK"
2025-07-07 08:51:29,646 - httpx - INFO - HTTP Request: POST https://api.telegram.org/bot8082065832:AAFMg57PUuHJzTt2YavoqCK5pEBYlhpVdYg/getUpdates "HTTP/1.1 200 OK"
2025-07-07 08:51:39,736 - httpx - INFO - HTTP Request: POST https://api.telegram.org/bot8082065832:AAFMg57PUuHJzTt2YavoqCK5pEBYlhpVdYg/getUpdates "HTTP/1.1 200 OK"
2025-07-07 08:51:42,820 - httpx - INFO - HTTP Request: POST https://api.telegram.org/bot8082065832:AAFMg57PUuHJzTt2YavoqCK5pEBYlhpVdYg/getUpdates "HTTP/1.1 409 Conflict"
2025-07-07 08:51:42,821 - telegram.ext.Application - ERROR - No error handlers are registered, logging exception.
Traceback (most recent call last):
  File "/home/ubuntu/.local/lib/python3.13/site-packages/telegram/ext/_utils/networkloop.py", line 115, in network_retry_loop
    if not await do_action():
           ^^^^^^^^^^^^^^^^^
  File "/home/ubuntu/.local/lib/python3.13/site-packages/telegram/ext/_utils/networkloop.py", line 108, in do_action
    return action_cb_task.result()
           ~~~~~~~~~~~~~~~~~~~~~^^
  File "/usr/lib/python3.13/asyncio/futures.py", line 199, in result
    raise self._exception.with_traceback(self._exception_tb)
  File "/usr/lib/python3.13/asyncio/tasks.py", line 304, in __step_run_and_handle_result
    result = coro.send(None)
  File "/home/ubuntu/.local/lib/python3.13/site-packages/telegram/ext/_updater.py", line 340, in polling_action_cb
    updates = await self.bot.get_updates(
              ^^^^^^^^^^^^^^^^^^^^^^^^^^^
    ...<3 lines>...
    )
    ^
  File "/home/ubuntu/.local/lib/python3.13/site-packages/telegram/ext/_extbot.py", line 669, in get_updates
    updates = await super().get_updates(
              ^^^^^^^^^^^^^^^^^^^^^^^^^^
    ...<9 lines>...
    )
    ^
  File "/home/ubuntu/.local/lib/python3.13/site-packages/telegram/_bot.py", line 4610, in get_updates
    await self._post(
    ^^^^^^^^^^^^^^^^^
    ...<7 lines>...
    ),
    ^
  File "/home/ubuntu/.local/lib/python3.13/site-packages/telegram/_bot.py", line 697, in _post
    return await self._do_post(
           ^^^^^^^^^^^^^^^^^^^^
    ...<6 lines>...
    )
    ^
  File "/home/ubuntu/.local/lib/python3.13/site-packages/telegram/ext/_extbot.py", line 369, in _do_post
    return await super()._do_post(
           ^^^^^^^^^^^^^^^^^^^^^^^
    ...<6 lines>...
    )
    ^
  File "/home/ubuntu/.local/lib/python3.13/site-packages/telegram/_bot.py", line 726, in _do_post
    result = await request.post(
             ^^^^^^^^^^^^^^^^^^^
    ...<6 lines>...
    )
    ^
  File "/home/ubuntu/.local/lib/python3.13/site-packages/telegram/request/_baserequest.py", line 197, in post
    result = await self._request_wrapper(
             ^^^^^^^^^^^^^^^^^^^^^^^^^^^^
    ...<7 lines>...
    )
    ^
  File "/home/ubuntu/.local/lib/python3.13/site-packages/telegram/request/_baserequest.py", line 374, in _request_wrapper
    raise exception
telegram.error.Conflict: Conflict: terminated by other getUpdates request; make sure that only one bot instance is running
2025-07-07 08:51:46,913 - httpx - INFO - HTTP Request: POST https://api.telegram.org/bot8082065832:AAFMg57PUuHJzTt2YavoqCK5pEBYlhpVdYg/getUpdates "HTTP/1.1 409 Conflict"
2025-07-07 08:51:46,914 - telegram.ext.Application - ERROR - No error handlers are registered, logging exception.
Traceback (most recent call last):
  File "/home/ubuntu/.local/lib/python3.13/site-packages/telegram/ext/_utils/networkloop.py", line 115, in network_retry_loop
    if not await do_action():
           ^^^^^^^^^^^^^^^^^
  File "/home/ubuntu/.local/lib/python3.13/site-packages/telegram/ext/_utils/networkloop.py", line 108, in do_action
    return action_cb_task.result()
           ~~~~~~~~~~~~~~~~~~~~~^^
  File "/usr/lib/python3.13/asyncio/futures.py", line 199, in result
    raise self._exception.with_traceback(self._exception_tb)
  File "/usr/lib/python3.13/asyncio/tasks.py", line 304, in __step_run_and_handle_result
    result = coro.send(None)
  File "/home/ubuntu/.local/lib/python3.13/site-packages/telegram/ext/_updater.py", line 340, in polling_action_cb
    updates = await self.bot.get_updates(
              ^^^^^^^^^^^^^^^^^^^^^^^^^^^
    ...<3 lines>...
    )
    ^
  File "/home/ubuntu/.local/lib/python3.13/site-packages/telegram/ext/_extbot.py", line 669, in get_updates
    updates = await super().get_updates(
              ^^^^^^^^^^^^^^^^^^^^^^^^^^
    ...<9 lines>...
    )
    ^
  File "/home/ubuntu/.local/lib/python3.13/site-packages/telegram/_bot.py", line 4610, in get_updates
    await self._post(
    ^^^^^^^^^^^^^^^^^
    ...<7 lines>...
    ),
    ^
  File "/home/ubuntu/.local/lib/python3.13/site-packages/telegram/_bot.py", line 697, in _post
    return await self._do_post(
           ^^^^^^^^^^^^^^^^^^^^
    ...<6 lines>...
    )
    ^
  File "/home/ubuntu/.local/lib/python3.13/site-packages/telegram/ext/_extbot.py", line 369, in _do_post
    return await super()._do_post(
           ^^^^^^^^^^^^^^^^^^^^^^^
    ...<6 lines>...
    )
    ^
  File "/home/ubuntu/.local/lib/python3.13/site-packages/telegram/_bot.py", line 726, in _do_post
    result = await request.post(
             ^^^^^^^^^^^^^^^^^^^
    ...<6 lines>...
    )
    ^
  File "/home/ubuntu/.local/lib/python3.13/site-packages/telegram/request/_baserequest.py", line 197, in post
    result = await self._request_wrapper(
             ^^^^^^^^^^^^^^^^^^^^^^^^^^^^
    ...<7 lines>...
    )
    ^
  File "/home/ubuntu/.local/lib/python3.13/site-packages/telegram/request/_baserequest.py", line 374, in _request_wrapper
    raise exception
telegram.error.Conflict: Conflict: terminated by other getUpdates request; make sure that only one bot instance is running
2025-07-07 08:51:53,913 - httpx - INFO - HTTP Request: POST https://api.telegram.org/bot8082065832:AAFMg57PUuHJzTt2YavoqCK5pEBYlhpVdYg/getUpdates "HTTP/1.1 200 OK"
2025-07-07 08:52:04,003 - httpx - INFO - HTTP Request: POST https://api.telegram.org/bot8082065832:AAFMg57PUuHJzTt2YavoqCK5pEBYlhpVdYg/getUpdates "HTTP/1.1 200 OK"
2025-07-07 08:52:14,093 - httpx - INFO - HTTP Request: POST https://api.telegram.org/bot8082065832:AAFMg57PUuHJzTt2YavoqCK5pEBYlhpVdYg/getUpdates "HTTP/1.1 200 OK"
2025-07-07 08:52:17,276 - httpx - INFO - HTTP Request: POST https://api.telegram.org/bot8082065832:AAFMg57PUuHJzTt2YavoqCK5pEBYlhpVdYg/getUpdates "HTTP/1.1 409 Conflict"
2025-07-07 08:52:17,277 - telegram.ext.Application - ERROR - No error handlers are registered, logging exception.
Traceback (most recent call last):
  File "/home/ubuntu/.local/lib/python3.13/site-packages/telegram/ext/_utils/networkloop.py", line 115, in network_retry_loop
    if not await do_action():
           ^^^^^^^^^^^^^^^^^
  File "/home/ubuntu/.local/lib/python3.13/site-packages/telegram/ext/_utils/networkloop.py", line 108, in do_action
    return action_cb_task.result()
           ~~~~~~~~~~~~~~~~~~~~~^^
  File "/usr/lib/python3.13/asyncio/futures.py", line 199, in result
    raise self._exception.with_traceback(self._exception_tb)
  File "/usr/lib/python3.13/asyncio/tasks.py", line 304, in __step_run_and_handle_result
    result = coro.send(None)
  File "/home/ubuntu/.local/lib/python3.13/site-packages/telegram/ext/_updater.py", line 340, in polling_action_cb
    updates = await self.bot.get_updates(
              ^^^^^^^^^^^^^^^^^^^^^^^^^^^
    ...<3 lines>...
    )
    ^
  File "/home/ubuntu/.local/lib/python3.13/site-packages/telegram/ext/_extbot.py", line 669, in get_updates
    updates = await super().get_updates(
              ^^^^^^^^^^^^^^^^^^^^^^^^^^
    ...<9 lines>...
    )
    ^
  File "/home/ubuntu/.local/lib/python3.13/site-packages/telegram/_bot.py", line 4610, in get_updates
    await self._post(
    ^^^^^^^^^^^^^^^^^
    ...<7 lines>...
    ),
    ^
  File "/home/ubuntu/.local/lib/python3.13/site-packages/telegram/_bot.py", line 697, in _post
    return await self._do_post(
           ^^^^^^^^^^^^^^^^^^^^
    ...<6 lines>...
    )
    ^
  File "/home/ubuntu/.local/lib/python3.13/site-packages/telegram/ext/_extbot.py", line 369, in _do_post
    return await super()._do_post(
           ^^^^^^^^^^^^^^^^^^^^^^^
    ...<6 lines>...
    )
    ^
  File "/home/ubuntu/.local/lib/python3.13/site-packages/telegram/_bot.py", line 726, in _do_post
    result = await request.post(
             ^^^^^^^^^^^^^^^^^^^
    ...<6 lines>...
    )
    ^
  File "/home/ubuntu/.local/lib/python3.13/site-packages/telegram/request/_baserequest.py", line 197, in post
    result = await self._request_wrapper(
             ^^^^^^^^^^^^^^^^^^^^^^^^^^^^
    ...<7 lines>...
    )
    ^
  File "/home/ubuntu/.local/lib/python3.13/site-packages/telegram/request/_baserequest.py", line 374, in _request_wrapper
    raise exception
telegram.error.Conflict: Conflict: terminated by other getUpdates request; make sure that only one bot instance is running
2025-07-07 08:52:21,369 - httpx - INFO - HTTP Request: POST https://api.telegram.org/bot8082065832:AAFMg57PUuHJzTt2YavoqCK5pEBYlhpVdYg/getUpdates "HTTP/1.1 409 Conflict"
2025-07-07 08:52:21,370 - telegram.ext.Application - ERROR - No error handlers are registered, logging exception.
Traceback (most recent call last):
  File "/home/ubuntu/.local/lib/python3.13/site-packages/telegram/ext/_utils/networkloop.py", line 115, in network_retry_loop
    if not await do_action():
           ^^^^^^^^^^^^^^^^^
  File "/home/ubuntu/.local/lib/python3.13/site-packages/telegram/ext/_utils/networkloop.py", line 108, in do_action
    return action_cb_task.result()
           ~~~~~~~~~~~~~~~~~~~~~^^
  File "/usr/lib/python3.13/asyncio/futures.py", line 199, in result
    raise self._exception.with_traceback(self._exception_tb)
  File "/usr/lib/python3.13/asyncio/tasks.py", line 304, in __step_run_and_handle_result
    result = coro.send(None)
  File "/home/ubuntu/.local/lib/python3.13/site-packages/telegram/ext/_updater.py", line 340, in polling_action_cb
    updates = await self.bot.get_updates(
              ^^^^^^^^^^^^^^^^^^^^^^^^^^^
    ...<3 lines>...
    )
    ^
  File "/home/ubuntu/.local/lib/python3.13/site-packages/telegram/ext/_extbot.py", line 669, in get_updates
    updates = await super().get_updates(
              ^^^^^^^^^^^^^^^^^^^^^^^^^^
    ...<9 lines>...
    )
    ^
  File "/home/ubuntu/.local/lib/python3.13/site-packages/telegram/_bot.py", line 4610, in get_updates
    await self._post(
    ^^^^^^^^^^^^^^^^^
    ...<7 lines>...
    ),
    ^
  File "/home/ubuntu/.local/lib/python3.13/site-packages/telegram/_bot.py", line 697, in _post
    return await self._do_post(
           ^^^^^^^^^^^^^^^^^^^^
    ...<6 lines>...
    )
    ^
  File "/home/ubuntu/.local/lib/python3.13/site-packages/telegram/ext/_extbot.py", line 369, in _do_post
    return await super()._do_post(
           ^^^^^^^^^^^^^^^^^^^^^^^
    ...<6 lines>...
    )
    ^
  File "/home/ubuntu/.local/lib/python3.13/site-packages/telegram/_bot.py", line 726, in _do_post
    result = await request.post(
             ^^^^^^^^^^^^^^^^^^^
    ...<6 lines>...
    )
    ^
  File "/home/ubuntu/.local/lib/python3.13/site-packages/telegram/request/_baserequest.py", line 197, in post
    result = await self._request_wrapper(
             ^^^^^^^^^^^^^^^^^^^^^^^^^^^^
    ...<7 lines>...
    )
    ^
  File "/home/ubuntu/.local/lib/python3.13/site-packages/telegram/request/_baserequest.py", line 374, in _request_wrapper
    raise exception
telegram.error.Conflict: Conflict: terminated by other getUpdates request; make sure that only one bot instance is running
2025-07-07 08:52:28,369 - httpx - INFO - HTTP Request: POST https://api.telegram.org/bot8082065832:AAFMg57PUuHJzTt2YavoqCK5pEBYlhpVdYg/getUpdates "HTTP/1.1 200 OK"
2025-07-07 08:52:38,458 - httpx - INFO - HTTP Request: POST https://api.telegram.org/bot8082065832:AAFMg57PUuHJzTt2YavoqCK5pEBYlhpVdYg/getUpdates "HTTP/1.1 200 OK"
2025-07-07 08:52:48,549 - httpx - INFO - HTTP Request: POST https://api.telegram.org/bot8082065832:AAFMg57PUuHJzTt2YavoqCK5pEBYlhpVdYg/getUpdates "HTTP/1.1 200 OK"
2025-07-07 08:52:51,641 - httpx - INFO - HTTP Request: POST https://api.telegram.org/bot8082065832:AAFMg57PUuHJzTt2YavoqCK5pEBYlhpVdYg/getUpdates "HTTP/1.1 409 Conflict"
2025-07-07 08:52:51,642 - telegram.ext.Application - ERROR - No error handlers are registered, logging exception.
Traceback (most recent call last):
  File "/home/ubuntu/.local/lib/python3.13/site-packages/telegram/ext/_utils/networkloop.py", line 115, in network_retry_loop
    if not await do_action():
           ^^^^^^^^^^^^^^^^^
  File "/home/ubuntu/.local/lib/python3.13/site-packages/telegram/ext/_utils/networkloop.py", line 108, in do_action
    return action_cb_task.result()
           ~~~~~~~~~~~~~~~~~~~~~^^
  File "/usr/lib/python3.13/asyncio/futures.py", line 199, in result
    raise self._exception.with_traceback(self._exception_tb)
  File "/usr/lib/python3.13/asyncio/tasks.py", line 304, in __step_run_and_handle_result
    result = coro.send(None)
  File "/home/ubuntu/.local/lib/python3.13/site-packages/telegram/ext/_updater.py", line 340, in polling_action_cb
    updates = await self.bot.get_updates(
              ^^^^^^^^^^^^^^^^^^^^^^^^^^^
    ...<3 lines>...
    )
    ^
  File "/home/ubuntu/.local/lib/python3.13/site-packages/telegram/ext/_extbot.py", line 669, in get_updates
    updates = await super().get_updates(
              ^^^^^^^^^^^^^^^^^^^^^^^^^^
    ...<9 lines>...
    )
    ^
  File "/home/ubuntu/.local/lib/python3.13/site-packages/telegram/_bot.py", line 4610, in get_updates
    await self._post(
    ^^^^^^^^^^^^^^^^^
    ...<7 lines>...
    ),
    ^
  File "/home/ubuntu/.local/lib/python3.13/site-packages/telegram/_bot.py", line 697, in _post
    return await self._do_post(
           ^^^^^^^^^^^^^^^^^^^^
    ...<6 lines>...
    )
    ^
  File "/home/ubuntu/.local/lib/python3.13/site-packages/telegram/ext/_extbot.py", line 369, in _do_post
    return await super()._do_post(
           ^^^^^^^^^^^^^^^^^^^^^^^
    ...<6 lines>...
    )
    ^
  File "/home/ubuntu/.local/lib/python3.13/site-packages/telegram/_bot.py", line 726, in _do_post
    result = await request.post(
             ^^^^^^^^^^^^^^^^^^^
    ...<6 lines>...
    )
    ^
  File "/home/ubuntu/.local/lib/python3.13/site-packages/telegram/request/_baserequest.py", line 197, in post
    result = await self._request_wrapper(
             ^^^^^^^^^^^^^^^^^^^^^^^^^^^^
    ...<7 lines>...
    )
    ^
  File "/home/ubuntu/.local/lib/python3.13/site-packages/telegram/request/_baserequest.py", line 374, in _request_wrapper
    raise exception
telegram.error.Conflict: Conflict: terminated by other getUpdates request; make sure that only one bot instance is running
2025-07-07 08:52:55,740 - httpx - INFO - HTTP Request: POST https://api.telegram.org/bot8082065832:AAFMg57PUuHJzTt2YavoqCK5pEBYlhpVdYg/getUpdates "HTTP/1.1 409 Conflict"
2025-07-07 08:52:55,740 - telegram.ext.Application - ERROR - No error handlers are registered, logging exception.
Traceback (most recent call last):
  File "/home/ubuntu/.local/lib/python3.13/site-packages/telegram/ext/_utils/networkloop.py", line 115, in network_retry_loop
    if not await do_action():
           ^^^^^^^^^^^^^^^^^
  File "/home/ubuntu/.local/lib/python3.13/site-packages/telegram/ext/_utils/networkloop.py", line 108, in do_action
    return action_cb_task.result()
           ~~~~~~~~~~~~~~~~~~~~~^^
  File "/usr/lib/python3.13/asyncio/futures.py", line 199, in result
    raise self._exception.with_traceback(self._exception_tb)
  File "/usr/lib/python3.13/asyncio/tasks.py", line 304, in __step_run_and_handle_result
    result = coro.send(None)
  File "/home/ubuntu/.local/lib/python3.13/site-packages/telegram/ext/_updater.py", line 340, in polling_action_cb
    updates = await self.bot.get_updates(
              ^^^^^^^^^^^^^^^^^^^^^^^^^^^
    ...<3 lines>...
    )
    ^
  File "/home/ubuntu/.local/lib/python3.13/site-packages/telegram/ext/_extbot.py", line 669, in get_updates
    updates = await super().get_updates(
              ^^^^^^^^^^^^^^^^^^^^^^^^^^
    ...<9 lines>...
    )
    ^
  File "/home/ubuntu/.local/lib/python3.13/site-packages/telegram/_bot.py", line 4610, in get_updates
    await self._post(
    ^^^^^^^^^^^^^^^^^
    ...<7 lines>...
    ),
    ^
  File "/home/ubuntu/.local/lib/python3.13/site-packages/telegram/_bot.py", line 697, in _post
    return await self._do_post(
           ^^^^^^^^^^^^^^^^^^^^
    ...<6 lines>...
    )
    ^
  File "/home/ubuntu/.local/lib/python3.13/site-packages/telegram/ext/_extbot.py", line 369, in _do_post
    return await super()._do_post(
           ^^^^^^^^^^^^^^^^^^^^^^^
    ...<6 lines>...
    )
    ^
  File "/home/ubuntu/.local/lib/python3.13/site-packages/telegram/_bot.py", line 726, in _do_post
    result = await request.post(
             ^^^^^^^^^^^^^^^^^^^
    ...<6 lines>...
    )
    ^
  File "/home/ubuntu/.local/lib/python3.13/site-packages/telegram/request/_baserequest.py", line 197, in post
    result = await self._request_wrapper(
             ^^^^^^^^^^^^^^^^^^^^^^^^^^^^
    ...<7 lines>...
    )
    ^
  File "/home/ubuntu/.local/lib/python3.13/site-packages/telegram/request/_baserequest.py", line 374, in _request_wrapper
    raise exception
telegram.error.Conflict: Conflict: terminated by other getUpdates request; make sure that only one bot instance is running
2025-07-07 08:53:00,945 - httpx - INFO - HTTP Request: POST https://api.telegram.org/bot8082065832:AAFMg57PUuHJzTt2YavoqCK5pEBYlhpVdYg/getUpdates "HTTP/1.1 200 OK"
2025-07-07 08:53:00,945 - telegram.ext.Application - INFO - Application is stopping. This might take a moment.
2025-07-07 08:53:00,945 - telegram.ext.Application - INFO - Application.stop() complete
2025-07-07 08:53:00,946 - root - ERROR - Event loop conflict. Cannot run in this environment.
2025-07-07 08:53:00,956 - asyncio - ERROR - Task exception was never retrieved
future: <Task finished name='Task-1' coro=<main_async() done, defined at /workspace/main_replit.py:16> exception=SystemExit(1)>
Traceback (most recent call last):
  File "/workspace/main.py", line 245, in run_bot
    await app.run_polling(drop_pending_updates=True)
          ~~~~~~~~~~~~~~~^^^^^^^^^^^^^^^^^^^^^^^^^^^
  File "/home/ubuntu/.local/lib/python3.13/site-packages/telegram/ext/_application.py", line 837, in run_polling
    return self.__run(
           ~~~~~~~~~~^
        updater_coroutine=self.updater.start_polling(
        ^^^^^^^^^^^^^^^^^^^^^^^^^^^^^^^^^^^^^^^^^^^^^
    ...<9 lines>...
        close_loop=close_loop,
        ^^^^^^^^^^^^^^^^^^^^^^
    )
    ^
  File "/home/ubuntu/.local/lib/python3.13/site-packages/telegram/ext/_application.py", line 1077, in __run
    loop.close()
    ~~~~~~~~~~^^
  File "/usr/lib/python3.13/asyncio/unix_events.py", line 70, in close
    super().close()
    ~~~~~~~~~~~~~^^
  File "/usr/lib/python3.13/asyncio/selector_events.py", line 101, in close
    raise RuntimeError("Cannot close a running event loop")
RuntimeError: Cannot close a running event loop

During handling of the above exception, another exception occurred:

Traceback (most recent call last):
  File "/workspace/main_replit.py", line 32, in <module>
    main()
    ~~~~^^
  File "/workspace/main_replit.py", line 26, in main
    asyncio.run(main_async())
    ~~~~~~~~~~~^^^^^^^^^^^^^^
  File "/home/ubuntu/.local/lib/python3.13/site-packages/nest_asyncio.py", line 30, in run
    return loop.run_until_complete(task)
           ~~~~~~~~~~~~~~~~~~~~~~~^^^^^^
  File "/home/ubuntu/.local/lib/python3.13/site-packages/nest_asyncio.py", line 92, in run_until_complete
    self._run_once()
    ~~~~~~~~~~~~~~^^
  File "/home/ubuntu/.local/lib/python3.13/site-packages/nest_asyncio.py", line 133, in _run_once
    handle._run()
    ~~~~~~~~~~~^^
  File "/usr/lib/python3.13/asyncio/events.py", line 89, in _run
    self._context.run(self._callback, *self._args)
    ~~~~~~~~~~~~~~~~~^^^^^^^^^^^^^^^^^^^^^^^^^^^^^
  File "/usr/lib/python3.13/asyncio/tasks.py", line 293, in __step
    self.__step_run_and_handle_result(exc)
    ~~~~~~~~~~~~~~~~~~~~~~~~~~~~~~~~~^^^^^
  File "/usr/lib/python3.13/asyncio/tasks.py", line 304, in __step_run_and_handle_result
    result = coro.send(None)
  File "/workspace/main_replit.py", line 20, in main_async
    await run_bot()
  File "/workspace/main.py", line 249, in run_bot
    sys.exit(1)
    ~~~~~~~~^^^
SystemExit: 1
2025-07-07 08:53:36,013 - httpx - INFO - HTTP Request: POST https://api.telegram.org/bot8082065832:AAFMg57PUuHJzTt2YavoqCK5pEBYlhpVdYg/getUpdates "HTTP/1.1 200 OK"
2025-07-07 08:53:46,101 - httpx - INFO - HTTP Request: POST https://api.telegram.org/bot8082065832:AAFMg57PUuHJzTt2YavoqCK5pEBYlhpVdYg/getUpdates "HTTP/1.1 200 OK"
2025-07-07 08:53:56,190 - httpx - INFO - HTTP Request: POST https://api.telegram.org/bot8082065832:AAFMg57PUuHJzTt2YavoqCK5pEBYlhpVdYg/getUpdates "HTTP/1.1 200 OK"
2025-07-07 08:54:06,276 - httpx - INFO - HTTP Request: POST https://api.telegram.org/bot8082065832:AAFMg57PUuHJzTt2YavoqCK5pEBYlhpVdYg/getUpdates "HTTP/1.1 200 OK"
2025-07-07 08:54:16,363 - httpx - INFO - HTTP Request: POST https://api.telegram.org/bot8082065832:AAFMg57PUuHJzTt2YavoqCK5pEBYlhpVdYg/getUpdates "HTTP/1.1 200 OK"
2025-07-07 08:54:26,449 - httpx - INFO - HTTP Request: POST https://api.telegram.org/bot8082065832:AAFMg57PUuHJzTt2YavoqCK5pEBYlhpVdYg/getUpdates "HTTP/1.1 200 OK"
2025-07-07 08:54:36,537 - httpx - INFO - HTTP Request: POST https://api.telegram.org/bot8082065832:AAFMg57PUuHJzTt2YavoqCK5pEBYlhpVdYg/getUpdates "HTTP/1.1 200 OK"
2025-07-07 08:54:46,622 - httpx - INFO - HTTP Request: POST https://api.telegram.org/bot8082065832:AAFMg57PUuHJzTt2YavoqCK5pEBYlhpVdYg/getUpdates "HTTP/1.1 200 OK"
2025-07-07 08:54:56,708 - httpx - INFO - HTTP Request: POST https://api.telegram.org/bot8082065832:AAFMg57PUuHJzTt2YavoqCK5pEBYlhpVdYg/getUpdates "HTTP/1.1 200 OK"
2025-07-07 08:55:06,794 - httpx - INFO - HTTP Request: POST https://api.telegram.org/bot8082065832:AAFMg57PUuHJzTt2YavoqCK5pEBYlhpVdYg/getUpdates "HTTP/1.1 200 OK"
2025-07-07 08:55:16,889 - httpx - INFO - HTTP Request: POST https://api.telegram.org/bot8082065832:AAFMg57PUuHJzTt2YavoqCK5pEBYlhpVdYg/getUpdates "HTTP/1.1 200 OK"
2025-07-07 08:55:26,979 - httpx - INFO - HTTP Request: POST https://api.telegram.org/bot8082065832:AAFMg57PUuHJzTt2YavoqCK5pEBYlhpVdYg/getUpdates "HTTP/1.1 200 OK"
2025-07-07 08:55:37,067 - httpx - INFO - HTTP Request: POST https://api.telegram.org/bot8082065832:AAFMg57PUuHJzTt2YavoqCK5pEBYlhpVdYg/getUpdates "HTTP/1.1 200 OK"
2025-07-07 08:55:47,153 - httpx - INFO - HTTP Request: POST https://api.telegram.org/bot8082065832:AAFMg57PUuHJzTt2YavoqCK5pEBYlhpVdYg/getUpdates "HTTP/1.1 200 OK"
2025-07-07 08:55:57,240 - httpx - INFO - HTTP Request: POST https://api.telegram.org/bot8082065832:AAFMg57PUuHJzTt2YavoqCK5pEBYlhpVdYg/getUpdates "HTTP/1.1 200 OK"
2025-07-07 08:56:07,326 - httpx - INFO - HTTP Request: POST https://api.telegram.org/bot8082065832:AAFMg57PUuHJzTt2YavoqCK5pEBYlhpVdYg/getUpdates "HTTP/1.1 200 OK"
2025-07-07 08:56:17,417 - httpx - INFO - HTTP Request: POST https://api.telegram.org/bot8082065832:AAFMg57PUuHJzTt2YavoqCK5pEBYlhpVdYg/getUpdates "HTTP/1.1 200 OK"
2025-07-07 08:56:27,504 - httpx - INFO - HTTP Request: POST https://api.telegram.org/bot8082065832:AAFMg57PUuHJzTt2YavoqCK5pEBYlhpVdYg/getUpdates "HTTP/1.1 200 OK"
2025-07-07 08:56:37,590 - httpx - INFO - HTTP Request: POST https://api.telegram.org/bot8082065832:AAFMg57PUuHJzTt2YavoqCK5pEBYlhpVdYg/getUpdates "HTTP/1.1 200 OK"
2025-07-07 08:56:47,676 - httpx - INFO - HTTP Request: POST https://api.telegram.org/bot8082065832:AAFMg57PUuHJzTt2YavoqCK5pEBYlhpVdYg/getUpdates "HTTP/1.1 200 OK"
2025-07-07 08:56:57,764 - httpx - INFO - HTTP Request: POST https://api.telegram.org/bot8082065832:AAFMg57PUuHJzTt2YavoqCK5pEBYlhpVdYg/getUpdates "HTTP/1.1 200 OK"
2025-07-07 08:57:07,860 - httpx - INFO - HTTP Request: POST https://api.telegram.org/bot8082065832:AAFMg57PUuHJzTt2YavoqCK5pEBYlhpVdYg/getUpdates "HTTP/1.1 200 OK"
2025-07-07 08:57:17,948 - httpx - INFO - HTTP Request: POST https://api.telegram.org/bot8082065832:AAFMg57PUuHJzTt2YavoqCK5pEBYlhpVdYg/getUpdates "HTTP/1.1 200 OK"
2025-07-07 08:57:28,038 - httpx - INFO - HTTP Request: POST https://api.telegram.org/bot8082065832:AAFMg57PUuHJzTt2YavoqCK5pEBYlhpVdYg/getUpdates "HTTP/1.1 200 OK"
2025-07-07 08:57:38,132 - httpx - INFO - HTTP Request: POST https://api.telegram.org/bot8082065832:AAFMg57PUuHJzTt2YavoqCK5pEBYlhpVdYg/getUpdates "HTTP/1.1 200 OK"
2025-07-07 08:57:48,219 - httpx - INFO - HTTP Request: POST https://api.telegram.org/bot8082065832:AAFMg57PUuHJzTt2YavoqCK5pEBYlhpVdYg/getUpdates "HTTP/1.1 200 OK"
2025-07-07 08:57:58,307 - httpx - INFO - HTTP Request: POST https://api.telegram.org/bot8082065832:AAFMg57PUuHJzTt2YavoqCK5pEBYlhpVdYg/getUpdates "HTTP/1.1 200 OK"
2025-07-07 08:58:08,397 - httpx - INFO - HTTP Request: POST https://api.telegram.org/bot8082065832:AAFMg57PUuHJzTt2YavoqCK5pEBYlhpVdYg/getUpdates "HTTP/1.1 200 OK"
2025-07-07 08:58:18,484 - httpx - INFO - HTTP Request: POST https://api.telegram.org/bot8082065832:AAFMg57PUuHJzTt2YavoqCK5pEBYlhpVdYg/getUpdates "HTTP/1.1 200 OK"
2025-07-07 08:58:28,570 - httpx - INFO - HTTP Request: POST https://api.telegram.org/bot8082065832:AAFMg57PUuHJzTt2YavoqCK5pEBYlhpVdYg/getUpdates "HTTP/1.1 200 OK"
2025-07-07 08:58:38,660 - httpx - INFO - HTTP Request: POST https://api.telegram.org/bot8082065832:AAFMg57PUuHJzTt2YavoqCK5pEBYlhpVdYg/getUpdates "HTTP/1.1 200 OK"
2025-07-07 08:58:48,749 - httpx - INFO - HTTP Request: POST https://api.telegram.org/bot8082065832:AAFMg57PUuHJzTt2YavoqCK5pEBYlhpVdYg/getUpdates "HTTP/1.1 200 OK"
2025-07-07 08:58:58,835 - httpx - INFO - HTTP Request: POST https://api.telegram.org/bot8082065832:AAFMg57PUuHJzTt2YavoqCK5pEBYlhpVdYg/getUpdates "HTTP/1.1 200 OK"
2025-07-07 08:59:08,922 - httpx - INFO - HTTP Request: POST https://api.telegram.org/bot8082065832:AAFMg57PUuHJzTt2YavoqCK5pEBYlhpVdYg/getUpdates "HTTP/1.1 200 OK"
2025-07-07 08:59:19,010 - httpx - INFO - HTTP Request: POST https://api.telegram.org/bot8082065832:AAFMg57PUuHJzTt2YavoqCK5pEBYlhpVdYg/getUpdates "HTTP/1.1 200 OK"
2025-07-07 08:59:29,096 - httpx - INFO - HTTP Request: POST https://api.telegram.org/bot8082065832:AAFMg57PUuHJzTt2YavoqCK5pEBYlhpVdYg/getUpdates "HTTP/1.1 200 OK"
2025-07-07 08:59:39,183 - httpx - INFO - HTTP Request: POST https://api.telegram.org/bot8082065832:AAFMg57PUuHJzTt2YavoqCK5pEBYlhpVdYg/getUpdates "HTTP/1.1 200 OK"
2025-07-07 08:59:49,269 - httpx - INFO - HTTP Request: POST https://api.telegram.org/bot8082065832:AAFMg57PUuHJzTt2YavoqCK5pEBYlhpVdYg/getUpdates "HTTP/1.1 200 OK"
2025-07-07 08:59:59,358 - httpx - INFO - HTTP Request: POST https://api.telegram.org/bot8082065832:AAFMg57PUuHJzTt2YavoqCK5pEBYlhpVdYg/getUpdates "HTTP/1.1 200 OK"
2025-07-07 09:00:09,445 - httpx - INFO - HTTP Request: POST https://api.telegram.org/bot8082065832:AAFMg57PUuHJzTt2YavoqCK5pEBYlhpVdYg/getUpdates "HTTP/1.1 200 OK"
2025-07-07 09:00:19,531 - httpx - INFO - HTTP Request: POST https://api.telegram.org/bot8082065832:AAFMg57PUuHJzTt2YavoqCK5pEBYlhpVdYg/getUpdates "HTTP/1.1 200 OK"
2025-07-07 09:00:29,618 - httpx - INFO - HTTP Request: POST https://api.telegram.org/bot8082065832:AAFMg57PUuHJzTt2YavoqCK5pEBYlhpVdYg/getUpdates "HTTP/1.1 200 OK"
2025-07-07 09:00:39,704 - httpx - INFO - HTTP Request: POST https://api.telegram.org/bot8082065832:AAFMg57PUuHJzTt2YavoqCK5pEBYlhpVdYg/getUpdates "HTTP/1.1 200 OK"
2025-07-07 09:00:49,793 - httpx - INFO - HTTP Request: POST https://api.telegram.org/bot8082065832:AAFMg57PUuHJzTt2YavoqCK5pEBYlhpVdYg/getUpdates "HTTP/1.1 200 OK"
2025-07-07 09:00:59,880 - httpx - INFO - HTTP Request: POST https://api.telegram.org/bot8082065832:AAFMg57PUuHJzTt2YavoqCK5pEBYlhpVdYg/getUpdates "HTTP/1.1 200 OK"
2025-07-07 09:01:09,969 - httpx - INFO - HTTP Request: POST https://api.telegram.org/bot8082065832:AAFMg57PUuHJzTt2YavoqCK5pEBYlhpVdYg/getUpdates "HTTP/1.1 200 OK"
2025-07-07 09:01:20,055 - httpx - INFO - HTTP Request: POST https://api.telegram.org/bot8082065832:AAFMg57PUuHJzTt2YavoqCK5pEBYlhpVdYg/getUpdates "HTTP/1.1 200 OK"
2025-07-07 09:01:30,144 - httpx - INFO - HTTP Request: POST https://api.telegram.org/bot8082065832:AAFMg57PUuHJzTt2YavoqCK5pEBYlhpVdYg/getUpdates "HTTP/1.1 200 OK"
2025-07-07 09:01:40,232 - httpx - INFO - HTTP Request: POST https://api.telegram.org/bot8082065832:AAFMg57PUuHJzTt2YavoqCK5pEBYlhpVdYg/getUpdates "HTTP/1.1 200 OK"
2025-07-07 09:01:50,318 - httpx - INFO - HTTP Request: POST https://api.telegram.org/bot8082065832:AAFMg57PUuHJzTt2YavoqCK5pEBYlhpVdYg/getUpdates "HTTP/1.1 200 OK"
2025-07-07 09:02:00,406 - httpx - INFO - HTTP Request: POST https://api.telegram.org/bot8082065832:AAFMg57PUuHJzTt2YavoqCK5pEBYlhpVdYg/getUpdates "HTTP/1.1 200 OK"
2025-07-07 09:02:10,509 - httpx - INFO - HTTP Request: POST https://api.telegram.org/bot8082065832:AAFMg57PUuHJzTt2YavoqCK5pEBYlhpVdYg/getUpdates "HTTP/1.1 200 OK"
2025-07-07 09:02:20,598 - httpx - INFO - HTTP Request: POST https://api.telegram.org/bot8082065832:AAFMg57PUuHJzTt2YavoqCK5pEBYlhpVdYg/getUpdates "HTTP/1.1 200 OK"
2025-07-07 09:02:30,686 - httpx - INFO - HTTP Request: POST https://api.telegram.org/bot8082065832:AAFMg57PUuHJzTt2YavoqCK5pEBYlhpVdYg/getUpdates "HTTP/1.1 200 OK"
2025-07-07 09:02:40,773 - httpx - INFO - HTTP Request: POST https://api.telegram.org/bot8082065832:AAFMg57PUuHJzTt2YavoqCK5pEBYlhpVdYg/getUpdates "HTTP/1.1 200 OK"
2025-07-07 09:02:50,860 - httpx - INFO - HTTP Request: POST https://api.telegram.org/bot8082065832:AAFMg57PUuHJzTt2YavoqCK5pEBYlhpVdYg/getUpdates "HTTP/1.1 200 OK"
2025-07-07 09:03:00,948 - httpx - INFO - HTTP Request: POST https://api.telegram.org/bot8082065832:AAFMg57PUuHJzTt2YavoqCK5pEBYlhpVdYg/getUpdates "HTTP/1.1 200 OK"
2025-07-07 09:03:11,035 - httpx - INFO - HTTP Request: POST https://api.telegram.org/bot8082065832:AAFMg57PUuHJzTt2YavoqCK5pEBYlhpVdYg/getUpdates "HTTP/1.1 200 OK"
2025-07-07 09:03:21,123 - httpx - INFO - HTTP Request: POST https://api.telegram.org/bot8082065832:AAFMg57PUuHJzTt2YavoqCK5pEBYlhpVdYg/getUpdates "HTTP/1.1 200 OK"
2025-07-07 09:03:31,209 - httpx - INFO - HTTP Request: POST https://api.telegram.org/bot8082065832:AAFMg57PUuHJzTt2YavoqCK5pEBYlhpVdYg/getUpdates "HTTP/1.1 200 OK"
2025-07-07 09:03:41,296 - httpx - INFO - HTTP Request: POST https://api.telegram.org/bot8082065832:AAFMg57PUuHJzTt2YavoqCK5pEBYlhpVdYg/getUpdates "HTTP/1.1 200 OK"
2025-07-07 09:03:51,383 - httpx - INFO - HTTP Request: POST https://api.telegram.org/bot8082065832:AAFMg57PUuHJzTt2YavoqCK5pEBYlhpVdYg/getUpdates "HTTP/1.1 200 OK"
2025-07-07 09:04:01,471 - httpx - INFO - HTTP Request: POST https://api.telegram.org/bot8082065832:AAFMg57PUuHJzTt2YavoqCK5pEBYlhpVdYg/getUpdates "HTTP/1.1 200 OK"
2025-07-07 09:04:11,571 - httpx - INFO - HTTP Request: POST https://api.telegram.org/bot8082065832:AAFMg57PUuHJzTt2YavoqCK5pEBYlhpVdYg/getUpdates "HTTP/1.1 200 OK"
2025-07-07 09:04:21,659 - httpx - INFO - HTTP Request: POST https://api.telegram.org/bot8082065832:AAFMg57PUuHJzTt2YavoqCK5pEBYlhpVdYg/getUpdates "HTTP/1.1 200 OK"
2025-07-07 09:04:31,745 - httpx - INFO - HTTP Request: POST https://api.telegram.org/bot8082065832:AAFMg57PUuHJzTt2YavoqCK5pEBYlhpVdYg/getUpdates "HTTP/1.1 200 OK"
2025-07-07 09:04:41,834 - httpx - INFO - HTTP Request: POST https://api.telegram.org/bot8082065832:AAFMg57PUuHJzTt2YavoqCK5pEBYlhpVdYg/getUpdates "HTTP/1.1 200 OK"
2025-07-07 09:04:51,920 - httpx - INFO - HTTP Request: POST https://api.telegram.org/bot8082065832:AAFMg57PUuHJzTt2YavoqCK5pEBYlhpVdYg/getUpdates "HTTP/1.1 200 OK"
2025-07-07 09:05:02,011 - httpx - INFO - HTTP Request: POST https://api.telegram.org/bot8082065832:AAFMg57PUuHJzTt2YavoqCK5pEBYlhpVdYg/getUpdates "HTTP/1.1 200 OK"
2025-07-07 09:05:12,100 - httpx - INFO - HTTP Request: POST https://api.telegram.org/bot8082065832:AAFMg57PUuHJzTt2YavoqCK5pEBYlhpVdYg/getUpdates "HTTP/1.1 200 OK"
2025-07-07 09:05:14,173 - root - INFO - 🔧 Using Replit-specific entry point
2025-07-07 09:05:14,173 - root - INFO - === QUIZ BOT STARTING ===
2025-07-07 09:05:14,173 - root - INFO - Python version: 3.13.3 (main, Apr  8 2025, 19:55:40) [GCC 14.2.0]
2025-07-07 09:05:14,173 - root - INFO - Environment debug info:
2025-07-07 09:05:14,173 - root - INFO -   Is Replit: False
2025-07-07 09:05:14,173 - root - INFO -   Replit URL: None
2025-07-07 09:05:14,173 - root - INFO - Initializing database...
2025-07-07 09:05:14,174 - root - INFO - Database initialized successfully
2025-07-07 09:05:14,174 - root - INFO - OpenAI API key loaded successfully
2025-07-07 09:05:14,174 - root - INFO - Creating Telegram application...
2025-07-07 09:05:14,220 - root - INFO - Telegram application created successfully
2025-07-07 09:05:14,221 - root - INFO - Registering handlers...
2025-07-07 09:05:14,221 - root - INFO - Handlers registered successfully
2025-07-07 09:05:14,221 - root - INFO - No webhook configured, will use polling mode
2025-07-07 09:05:14,222 - root - INFO - 📡 Starting polling mode...
2025-07-07 09:05:14,488 - httpx - INFO - HTTP Request: POST https://api.telegram.org/bot8082065832:AAFMg57PUuHJzTt2YavoqCK5pEBYlhpVdYg/getMe "HTTP/1.1 200 OK"
2025-07-07 09:05:14,575 - httpx - INFO - HTTP Request: POST https://api.telegram.org/bot8082065832:AAFMg57PUuHJzTt2YavoqCK5pEBYlhpVdYg/deleteWebhook "HTTP/1.1 200 OK"
2025-07-07 09:05:14,576 - telegram.ext.Application - INFO - Application started
2025-07-07 09:05:14,831 - httpx - INFO - HTTP Request: POST https://api.telegram.org/bot8082065832:AAFMg57PUuHJzTt2YavoqCK5pEBYlhpVdYg/getUpdates "HTTP/1.1 409 Conflict"
2025-07-07 09:05:14,832 - telegram.ext.Application - ERROR - No error handlers are registered, logging exception.
Traceback (most recent call last):
  File "/home/ubuntu/.local/lib/python3.13/site-packages/telegram/ext/_utils/networkloop.py", line 115, in network_retry_loop
    if not await do_action():
           ^^^^^^^^^^^^^^^^^
  File "/home/ubuntu/.local/lib/python3.13/site-packages/telegram/ext/_utils/networkloop.py", line 108, in do_action
    return action_cb_task.result()
           ~~~~~~~~~~~~~~~~~~~~~^^
  File "/usr/lib/python3.13/asyncio/futures.py", line 199, in result
    raise self._exception.with_traceback(self._exception_tb)
  File "/usr/lib/python3.13/asyncio/tasks.py", line 304, in __step_run_and_handle_result
    result = coro.send(None)
  File "/home/ubuntu/.local/lib/python3.13/site-packages/telegram/ext/_updater.py", line 340, in polling_action_cb
    updates = await self.bot.get_updates(
              ^^^^^^^^^^^^^^^^^^^^^^^^^^^
    ...<3 lines>...
    )
    ^
  File "/home/ubuntu/.local/lib/python3.13/site-packages/telegram/ext/_extbot.py", line 669, in get_updates
    updates = await super().get_updates(
              ^^^^^^^^^^^^^^^^^^^^^^^^^^
    ...<9 lines>...
    )
    ^
  File "/home/ubuntu/.local/lib/python3.13/site-packages/telegram/_bot.py", line 4610, in get_updates
    await self._post(
    ^^^^^^^^^^^^^^^^^
    ...<7 lines>...
    ),
    ^
  File "/home/ubuntu/.local/lib/python3.13/site-packages/telegram/_bot.py", line 697, in _post
    return await self._do_post(
           ^^^^^^^^^^^^^^^^^^^^
    ...<6 lines>...
    )
    ^
  File "/home/ubuntu/.local/lib/python3.13/site-packages/telegram/ext/_extbot.py", line 369, in _do_post
    return await super()._do_post(
           ^^^^^^^^^^^^^^^^^^^^^^^
    ...<6 lines>...
    )
    ^
  File "/home/ubuntu/.local/lib/python3.13/site-packages/telegram/_bot.py", line 726, in _do_post
    result = await request.post(
             ^^^^^^^^^^^^^^^^^^^
    ...<6 lines>...
    )
    ^
  File "/home/ubuntu/.local/lib/python3.13/site-packages/telegram/request/_baserequest.py", line 197, in post
    result = await self._request_wrapper(
             ^^^^^^^^^^^^^^^^^^^^^^^^^^^^
    ...<7 lines>...
    )
    ^
  File "/home/ubuntu/.local/lib/python3.13/site-packages/telegram/request/_baserequest.py", line 374, in _request_wrapper
    raise exception
telegram.error.Conflict: Conflict: terminated by other getUpdates request; make sure that only one bot instance is running
2025-07-07 09:05:18,921 - httpx - INFO - HTTP Request: POST https://api.telegram.org/bot8082065832:AAFMg57PUuHJzTt2YavoqCK5pEBYlhpVdYg/getUpdates "HTTP/1.1 409 Conflict"
2025-07-07 09:05:18,922 - telegram.ext.Application - ERROR - No error handlers are registered, logging exception.
Traceback (most recent call last):
  File "/home/ubuntu/.local/lib/python3.13/site-packages/telegram/ext/_utils/networkloop.py", line 115, in network_retry_loop
    if not await do_action():
           ^^^^^^^^^^^^^^^^^
  File "/home/ubuntu/.local/lib/python3.13/site-packages/telegram/ext/_utils/networkloop.py", line 108, in do_action
    return action_cb_task.result()
           ~~~~~~~~~~~~~~~~~~~~~^^
  File "/usr/lib/python3.13/asyncio/futures.py", line 199, in result
    raise self._exception.with_traceback(self._exception_tb)
  File "/usr/lib/python3.13/asyncio/tasks.py", line 304, in __step_run_and_handle_result
    result = coro.send(None)
  File "/home/ubuntu/.local/lib/python3.13/site-packages/telegram/ext/_updater.py", line 340, in polling_action_cb
    updates = await self.bot.get_updates(
              ^^^^^^^^^^^^^^^^^^^^^^^^^^^
    ...<3 lines>...
    )
    ^
  File "/home/ubuntu/.local/lib/python3.13/site-packages/telegram/ext/_extbot.py", line 669, in get_updates
    updates = await super().get_updates(
              ^^^^^^^^^^^^^^^^^^^^^^^^^^
    ...<9 lines>...
    )
    ^
  File "/home/ubuntu/.local/lib/python3.13/site-packages/telegram/_bot.py", line 4610, in get_updates
    await self._post(
    ^^^^^^^^^^^^^^^^^
    ...<7 lines>...
    ),
    ^
  File "/home/ubuntu/.local/lib/python3.13/site-packages/telegram/_bot.py", line 697, in _post
    return await self._do_post(
           ^^^^^^^^^^^^^^^^^^^^
    ...<6 lines>...
    )
    ^
  File "/home/ubuntu/.local/lib/python3.13/site-packages/telegram/ext/_extbot.py", line 369, in _do_post
    return await super()._do_post(
           ^^^^^^^^^^^^^^^^^^^^^^^
    ...<6 lines>...
    )
    ^
  File "/home/ubuntu/.local/lib/python3.13/site-packages/telegram/_bot.py", line 726, in _do_post
    result = await request.post(
             ^^^^^^^^^^^^^^^^^^^
    ...<6 lines>...
    )
    ^
  File "/home/ubuntu/.local/lib/python3.13/site-packages/telegram/request/_baserequest.py", line 197, in post
    result = await self._request_wrapper(
             ^^^^^^^^^^^^^^^^^^^^^^^^^^^^
    ...<7 lines>...
    )
    ^
  File "/home/ubuntu/.local/lib/python3.13/site-packages/telegram/request/_baserequest.py", line 374, in _request_wrapper
    raise exception
telegram.error.Conflict: Conflict: terminated by other getUpdates request; make sure that only one bot instance is running
2025-07-07 09:05:20,005 - httpx - INFO - HTTP Request: POST https://api.telegram.org/bot8082065832:AAFMg57PUuHJzTt2YavoqCK5pEBYlhpVdYg/getUpdates "HTTP/1.1 409 Conflict"
2025-07-07 09:05:20,006 - telegram.ext.Application - ERROR - No error handlers are registered, logging exception.
Traceback (most recent call last):
  File "/home/ubuntu/.local/lib/python3.13/site-packages/telegram/ext/_utils/networkloop.py", line 115, in network_retry_loop
    if not await do_action():
           ^^^^^^^^^^^^^^^^^
  File "/home/ubuntu/.local/lib/python3.13/site-packages/telegram/ext/_utils/networkloop.py", line 108, in do_action
    return action_cb_task.result()
           ~~~~~~~~~~~~~~~~~~~~~^^
  File "/usr/lib/python3.13/asyncio/futures.py", line 199, in result
    raise self._exception.with_traceback(self._exception_tb)
  File "/usr/lib/python3.13/asyncio/tasks.py", line 304, in __step_run_and_handle_result
    result = coro.send(None)
  File "/home/ubuntu/.local/lib/python3.13/site-packages/telegram/ext/_updater.py", line 340, in polling_action_cb
    updates = await self.bot.get_updates(
              ^^^^^^^^^^^^^^^^^^^^^^^^^^^
    ...<3 lines>...
    )
    ^
  File "/home/ubuntu/.local/lib/python3.13/site-packages/telegram/ext/_extbot.py", line 669, in get_updates
    updates = await super().get_updates(
              ^^^^^^^^^^^^^^^^^^^^^^^^^^
    ...<9 lines>...
    )
    ^
  File "/home/ubuntu/.local/lib/python3.13/site-packages/telegram/_bot.py", line 4610, in get_updates
    await self._post(
    ^^^^^^^^^^^^^^^^^
    ...<7 lines>...
    ),
    ^
  File "/home/ubuntu/.local/lib/python3.13/site-packages/telegram/_bot.py", line 697, in _post
    return await self._do_post(
           ^^^^^^^^^^^^^^^^^^^^
    ...<6 lines>...
    )
    ^
  File "/home/ubuntu/.local/lib/python3.13/site-packages/telegram/ext/_extbot.py", line 369, in _do_post
    return await super()._do_post(
           ^^^^^^^^^^^^^^^^^^^^^^^
    ...<6 lines>...
    )
    ^
  File "/home/ubuntu/.local/lib/python3.13/site-packages/telegram/_bot.py", line 726, in _do_post
    result = await request.post(
             ^^^^^^^^^^^^^^^^^^^
    ...<6 lines>...
    )
    ^
  File "/home/ubuntu/.local/lib/python3.13/site-packages/telegram/request/_baserequest.py", line 197, in post
    result = await self._request_wrapper(
             ^^^^^^^^^^^^^^^^^^^^^^^^^^^^
    ...<7 lines>...
    )
    ^
  File "/home/ubuntu/.local/lib/python3.13/site-packages/telegram/request/_baserequest.py", line 374, in _request_wrapper
    raise exception
telegram.error.Conflict: Conflict: terminated by other getUpdates request; make sure that only one bot instance is running
2025-07-07 09:05:24,271 - httpx - INFO - HTTP Request: POST https://api.telegram.org/bot8082065832:AAFMg57PUuHJzTt2YavoqCK5pEBYlhpVdYg/getUpdates "HTTP/1.1 409 Conflict"
2025-07-07 09:05:24,272 - telegram.ext.Application - ERROR - No error handlers are registered, logging exception.
Traceback (most recent call last):
  File "/home/ubuntu/.local/lib/python3.13/site-packages/telegram/ext/_utils/networkloop.py", line 115, in network_retry_loop
    if not await do_action():
           ^^^^^^^^^^^^^^^^^
  File "/home/ubuntu/.local/lib/python3.13/site-packages/telegram/ext/_utils/networkloop.py", line 108, in do_action
    return action_cb_task.result()
           ~~~~~~~~~~~~~~~~~~~~~^^
  File "/usr/lib/python3.13/asyncio/futures.py", line 199, in result
    raise self._exception.with_traceback(self._exception_tb)
  File "/usr/lib/python3.13/asyncio/tasks.py", line 304, in __step_run_and_handle_result
    result = coro.send(None)
  File "/home/ubuntu/.local/lib/python3.13/site-packages/telegram/ext/_updater.py", line 340, in polling_action_cb
    updates = await self.bot.get_updates(
              ^^^^^^^^^^^^^^^^^^^^^^^^^^^
    ...<3 lines>...
    )
    ^
  File "/home/ubuntu/.local/lib/python3.13/site-packages/telegram/ext/_extbot.py", line 669, in get_updates
    updates = await super().get_updates(
              ^^^^^^^^^^^^^^^^^^^^^^^^^^
    ...<9 lines>...
    )
    ^
  File "/home/ubuntu/.local/lib/python3.13/site-packages/telegram/_bot.py", line 4610, in get_updates
    await self._post(
    ^^^^^^^^^^^^^^^^^
    ...<7 lines>...
    ),
    ^
  File "/home/ubuntu/.local/lib/python3.13/site-packages/telegram/_bot.py", line 697, in _post
    return await self._do_post(
           ^^^^^^^^^^^^^^^^^^^^
    ...<6 lines>...
    )
    ^
  File "/home/ubuntu/.local/lib/python3.13/site-packages/telegram/ext/_extbot.py", line 369, in _do_post
    return await super()._do_post(
           ^^^^^^^^^^^^^^^^^^^^^^^
    ...<6 lines>...
    )
    ^
  File "/home/ubuntu/.local/lib/python3.13/site-packages/telegram/_bot.py", line 726, in _do_post
    result = await request.post(
             ^^^^^^^^^^^^^^^^^^^
    ...<6 lines>...
    )
    ^
  File "/home/ubuntu/.local/lib/python3.13/site-packages/telegram/request/_baserequest.py", line 197, in post
    result = await self._request_wrapper(
             ^^^^^^^^^^^^^^^^^^^^^^^^^^^^
    ...<7 lines>...
    )
    ^
  File "/home/ubuntu/.local/lib/python3.13/site-packages/telegram/request/_baserequest.py", line 374, in _request_wrapper
    raise exception
telegram.error.Conflict: Conflict: terminated by other getUpdates request; make sure that only one bot instance is running
2025-07-07 09:05:29,191 - telegram.ext.Updater - ERROR - Error while calling `get_updates` one more time to mark all fetched updates as read: %s. Suppressing error to ensure graceful shutdown. When polling for updates is restarted, updates may be fetched again. Please adjust timeouts via `ApplicationBuilder` or the parameter `get_updates_request` of `Bot`.
Traceback (most recent call last):
  File "/home/ubuntu/.local/lib/python3.13/site-packages/httpx/_transports/default.py", line 101, in map_httpcore_exceptions
    yield
  File "/home/ubuntu/.local/lib/python3.13/site-packages/httpx/_transports/default.py", line 394, in handle_async_request
    resp = await self._pool.handle_async_request(req)
           ^^^^^^^^^^^^^^^^^^^^^^^^^^^^^^^^^^^^^^^^^^
  File "/home/ubuntu/.local/lib/python3.13/site-packages/httpcore/_async/connection_pool.py", line 256, in handle_async_request
    raise exc from None
  File "/home/ubuntu/.local/lib/python3.13/site-packages/httpcore/_async/connection_pool.py", line 236, in handle_async_request
    response = await connection.handle_async_request(
               ^^^^^^^^^^^^^^^^^^^^^^^^^^^^^^^^^^^^^^
        pool_request.request
        ^^^^^^^^^^^^^^^^^^^^
    )
    ^
  File "/home/ubuntu/.local/lib/python3.13/site-packages/httpcore/_async/connection.py", line 103, in handle_async_request
    return await self._connection.handle_async_request(request)
           ^^^^^^^^^^^^^^^^^^^^^^^^^^^^^^^^^^^^^^^^^^^^^^^^^^^^
  File "/home/ubuntu/.local/lib/python3.13/site-packages/httpcore/_async/http11.py", line 136, in handle_async_request
    raise exc
  File "/home/ubuntu/.local/lib/python3.13/site-packages/httpcore/_async/http11.py", line 106, in handle_async_request
    ) = await self._receive_response_headers(**kwargs)
        ^^^^^^^^^^^^^^^^^^^^^^^^^^^^^^^^^^^^^^^^^^^^^^
  File "/home/ubuntu/.local/lib/python3.13/site-packages/httpcore/_async/http11.py", line 177, in _receive_response_headers
    event = await self._receive_event(timeout=timeout)
            ^^^^^^^^^^^^^^^^^^^^^^^^^^^^^^^^^^^^^^^^^^
  File "/home/ubuntu/.local/lib/python3.13/site-packages/httpcore/_async/http11.py", line 217, in _receive_event
    data = await self._network_stream.read(
           ^^^^^^^^^^^^^^^^^^^^^^^^^^^^^^^^
        self.READ_NUM_BYTES, timeout=timeout
        ^^^^^^^^^^^^^^^^^^^^^^^^^^^^^^^^^^^^
    )
    ^
  File "/home/ubuntu/.local/lib/python3.13/site-packages/httpcore/_backends/anyio.py", line 32, in read
    with map_exceptions(exc_map):
         ~~~~~~~~~~~~~~^^^^^^^^^
  File "/usr/lib/python3.13/contextlib.py", line 162, in __exit__
    self.gen.throw(value)
    ~~~~~~~~~~~~~~^^^^^^^
  File "/home/ubuntu/.local/lib/python3.13/site-packages/httpcore/_exceptions.py", line 14, in map_exceptions
    raise to_exc(exc) from exc
httpcore.ReadTimeout

The above exception was the direct cause of the following exception:

Traceback (most recent call last):
  File "/home/ubuntu/.local/lib/python3.13/site-packages/telegram/request/_httpxrequest.py", line 273, in do_request
    res = await self._client.request(
          ^^^^^^^^^^^^^^^^^^^^^^^^^^^
    ...<6 lines>...
    )
    ^
  File "/home/ubuntu/.local/lib/python3.13/site-packages/httpx/_client.py", line 1540, in request
    return await self.send(request, auth=auth, follow_redirects=follow_redirects)
           ^^^^^^^^^^^^^^^^^^^^^^^^^^^^^^^^^^^^^^^^^^^^^^^^^^^^^^^^^^^^^^^^^^^^^^
  File "/home/ubuntu/.local/lib/python3.13/site-packages/httpx/_client.py", line 1629, in send
    response = await self._send_handling_auth(
               ^^^^^^^^^^^^^^^^^^^^^^^^^^^^^^^
    ...<4 lines>...
    )
    ^
  File "/home/ubuntu/.local/lib/python3.13/site-packages/httpx/_client.py", line 1657, in _send_handling_auth
    response = await self._send_handling_redirects(
               ^^^^^^^^^^^^^^^^^^^^^^^^^^^^^^^^^^^^
    ...<3 lines>...
    )
    ^
  File "/home/ubuntu/.local/lib/python3.13/site-packages/httpx/_client.py", line 1694, in _send_handling_redirects
    response = await self._send_single_request(request)
               ^^^^^^^^^^^^^^^^^^^^^^^^^^^^^^^^^^^^^^^^
  File "/home/ubuntu/.local/lib/python3.13/site-packages/httpx/_client.py", line 1730, in _send_single_request
    response = await transport.handle_async_request(request)
               ^^^^^^^^^^^^^^^^^^^^^^^^^^^^^^^^^^^^^^^^^^^^^
  File "/home/ubuntu/.local/lib/python3.13/site-packages/httpx/_transports/default.py", line 393, in handle_async_request
    with map_httpcore_exceptions():
         ~~~~~~~~~~~~~~~~~~~~~~~^^
  File "/usr/lib/python3.13/contextlib.py", line 162, in __exit__
    self.gen.throw(value)
    ~~~~~~~~~~~~~~^^^^^^^
  File "/home/ubuntu/.local/lib/python3.13/site-packages/httpx/_transports/default.py", line 118, in map_httpcore_exceptions
    raise mapped_exc(message) from exc
httpx.ReadTimeout

The above exception was the direct cause of the following exception:

Traceback (most recent call last):
  File "/home/ubuntu/.local/lib/python3.13/site-packages/telegram/ext/_updater.py", line 399, in _get_updates_cleanup
    await self.bot.get_updates(
    ...<4 lines>...
    )
  File "/home/ubuntu/.local/lib/python3.13/site-packages/telegram/ext/_extbot.py", line 669, in get_updates
    updates = await super().get_updates(
              ^^^^^^^^^^^^^^^^^^^^^^^^^^
    ...<9 lines>...
    )
    ^
  File "/home/ubuntu/.local/lib/python3.13/site-packages/telegram/_bot.py", line 4610, in get_updates
    await self._post(
    ^^^^^^^^^^^^^^^^^
    ...<7 lines>...
    ),
    ^
  File "/home/ubuntu/.local/lib/python3.13/site-packages/telegram/_bot.py", line 697, in _post
    return await self._do_post(
           ^^^^^^^^^^^^^^^^^^^^
    ...<6 lines>...
    )
    ^
  File "/home/ubuntu/.local/lib/python3.13/site-packages/telegram/ext/_extbot.py", line 369, in _do_post
    return await super()._do_post(
           ^^^^^^^^^^^^^^^^^^^^^^^
    ...<6 lines>...
    )
    ^
  File "/home/ubuntu/.local/lib/python3.13/site-packages/telegram/_bot.py", line 726, in _do_post
    result = await request.post(
             ^^^^^^^^^^^^^^^^^^^
    ...<6 lines>...
    )
    ^
  File "/home/ubuntu/.local/lib/python3.13/site-packages/telegram/request/_baserequest.py", line 197, in post
    result = await self._request_wrapper(
             ^^^^^^^^^^^^^^^^^^^^^^^^^^^^
    ...<7 lines>...
    )
    ^
  File "/home/ubuntu/.local/lib/python3.13/site-packages/telegram/request/_baserequest.py", line 304, in _request_wrapper
    code, payload = await self.do_request(
                    ^^^^^^^^^^^^^^^^^^^^^^
    ...<7 lines>...
    )
    ^
  File "/home/ubuntu/.local/lib/python3.13/site-packages/telegram/request/_httpxrequest.py", line 290, in do_request
    raise TimedOut from err
telegram.error.TimedOut: Timed out
2025-07-07 09:05:29,195 - telegram.ext.Application - INFO - Application is stopping. This might take a moment.
2025-07-07 09:05:29,196 - telegram.ext.Application - INFO - Application.stop() complete
2025-07-07 09:05:29,196 - root - ERROR - Event loop conflict. Cannot run in this environment.
2025-07-07 09:05:29,206 - asyncio - ERROR - Task exception was never retrieved
future: <Task finished name='Task-1' coro=<main_async() done, defined at /workspace/main_replit.py:16> exception=SystemExit(1)>
Traceback (most recent call last):
  File "/workspace/main.py", line 245, in run_bot
    await app.run_polling(drop_pending_updates=True)
          ~~~~~~~~~~~~~~~^^^^^^^^^^^^^^^^^^^^^^^^^^^
  File "/home/ubuntu/.local/lib/python3.13/site-packages/telegram/ext/_application.py", line 837, in run_polling
    return self.__run(
           ~~~~~~~~~~^
        updater_coroutine=self.updater.start_polling(
        ^^^^^^^^^^^^^^^^^^^^^^^^^^^^^^^^^^^^^^^^^^^^^
    ...<9 lines>...
        close_loop=close_loop,
        ^^^^^^^^^^^^^^^^^^^^^^
    )
    ^
  File "/home/ubuntu/.local/lib/python3.13/site-packages/telegram/ext/_application.py", line 1077, in __run
    loop.close()
    ~~~~~~~~~~^^
  File "/usr/lib/python3.13/asyncio/unix_events.py", line 70, in close
    super().close()
    ~~~~~~~~~~~~~^^
  File "/usr/lib/python3.13/asyncio/selector_events.py", line 101, in close
    raise RuntimeError("Cannot close a running event loop")
RuntimeError: Cannot close a running event loop

During handling of the above exception, another exception occurred:

Traceback (most recent call last):
  File "/workspace/main_replit.py", line 32, in <module>
    main()
    ~~~~^^
  File "/workspace/main_replit.py", line 26, in main
    asyncio.run(main_async())
    ~~~~~~~~~~~^^^^^^^^^^^^^^
  File "/home/ubuntu/.local/lib/python3.13/site-packages/nest_asyncio.py", line 30, in run
    return loop.run_until_complete(task)
           ~~~~~~~~~~~~~~~~~~~~~~~^^^^^^
  File "/home/ubuntu/.local/lib/python3.13/site-packages/nest_asyncio.py", line 92, in run_until_complete
    self._run_once()
    ~~~~~~~~~~~~~~^^
  File "/home/ubuntu/.local/lib/python3.13/site-packages/nest_asyncio.py", line 133, in _run_once
    handle._run()
    ~~~~~~~~~~~^^
  File "/usr/lib/python3.13/asyncio/events.py", line 89, in _run
    self._context.run(self._callback, *self._args)
    ~~~~~~~~~~~~~~~~~^^^^^^^^^^^^^^^^^^^^^^^^^^^^^
  File "/usr/lib/python3.13/asyncio/tasks.py", line 293, in __step
    self.__step_run_and_handle_result(exc)
    ~~~~~~~~~~~~~~~~~~~~~~~~~~~~~~~~~^^^^^
  File "/usr/lib/python3.13/asyncio/tasks.py", line 304, in __step_run_and_handle_result
    result = coro.send(None)
  File "/workspace/main_replit.py", line 20, in main_async
    await run_bot()
  File "/workspace/main.py", line 249, in run_bot
    sys.exit(1)
    ~~~~~~~~^^^
SystemExit: 1
2025-07-07 09:05:36,613 - httpx - INFO - HTTP Request: POST https://api.telegram.org/bot8082065832:AAFMg57PUuHJzTt2YavoqCK5pEBYlhpVdYg/getUpdates "HTTP/1.1 200 OK"
2025-07-07 09:05:45,943 - httpx - INFO - HTTP Request: POST https://api.telegram.org/bot8082065832:AAFMg57PUuHJzTt2YavoqCK5pEBYlhpVdYg/getUpdates "HTTP/1.1 200 OK"
2025-07-07 09:05:45,943 - telegram.ext.Application - INFO - Application is stopping. This might take a moment.
2025-07-07 09:05:45,943 - telegram.ext.Application - INFO - Application.stop() complete
2025-07-07 09:05:45,944 - root - ERROR - Event loop conflict. Cannot run in this environment.
2025-07-07 09:05:45,954 - asyncio - ERROR - Task exception was never retrieved
future: <Task finished name='Task-1' coro=<main_async() done, defined at /workspace/main_replit.py:16> exception=SystemExit(1)>
Traceback (most recent call last):
  File "/workspace/main.py", line 245, in run_bot
    await app.run_polling(drop_pending_updates=True)
          ~~~~~~~~~~~~~~~^^^^^^^^^^^^^^^^^^^^^^^^^^^
  File "/home/ubuntu/.local/lib/python3.13/site-packages/telegram/ext/_application.py", line 837, in run_polling
    return self.__run(
           ~~~~~~~~~~^
        updater_coroutine=self.updater.start_polling(
        ^^^^^^^^^^^^^^^^^^^^^^^^^^^^^^^^^^^^^^^^^^^^^
    ...<9 lines>...
        close_loop=close_loop,
        ^^^^^^^^^^^^^^^^^^^^^^
    )
    ^
  File "/home/ubuntu/.local/lib/python3.13/site-packages/telegram/ext/_application.py", line 1077, in __run
    loop.close()
    ~~~~~~~~~~^^
  File "/usr/lib/python3.13/asyncio/unix_events.py", line 70, in close
    super().close()
    ~~~~~~~~~~~~~^^
  File "/usr/lib/python3.13/asyncio/selector_events.py", line 101, in close
    raise RuntimeError("Cannot close a running event loop")
RuntimeError: Cannot close a running event loop

During handling of the above exception, another exception occurred:

Traceback (most recent call last):
  File "/workspace/main_replit.py", line 32, in <module>
    main()
    ~~~~^^
  File "/workspace/main_replit.py", line 26, in main
    asyncio.run(main_async())
    ~~~~~~~~~~~^^^^^^^^^^^^^^
  File "/home/ubuntu/.local/lib/python3.13/site-packages/nest_asyncio.py", line 30, in run
    return loop.run_until_complete(task)
           ~~~~~~~~~~~~~~~~~~~~~~~^^^^^^
  File "/home/ubuntu/.local/lib/python3.13/site-packages/nest_asyncio.py", line 92, in run_until_complete
    self._run_once()
    ~~~~~~~~~~~~~~^^
  File "/home/ubuntu/.local/lib/python3.13/site-packages/nest_asyncio.py", line 133, in _run_once
    handle._run()
    ~~~~~~~~~~~^^
  File "/usr/lib/python3.13/asyncio/events.py", line 89, in _run
    self._context.run(self._callback, *self._args)
    ~~~~~~~~~~~~~~~~~^^^^^^^^^^^^^^^^^^^^^^^^^^^^^
  File "/usr/lib/python3.13/asyncio/tasks.py", line 293, in __step
    self.__step_run_and_handle_result(exc)
    ~~~~~~~~~~~~~~~~~~~~~~~~~~~~~~~~~^^^^^
  File "/usr/lib/python3.13/asyncio/tasks.py", line 304, in __step_run_and_handle_result
    result = coro.send(None)
  File "/workspace/main_replit.py", line 20, in main_async
    await run_bot()
  File "/workspace/main.py", line 249, in run_bot
    sys.exit(1)
    ~~~~~~~~^^^
SystemExit: 1
2025-07-07 09:06:07,450 - root - INFO - 🔧 Using Replit-specific entry point
2025-07-07 09:06:07,450 - root - INFO - === QUIZ BOT STARTING ===
2025-07-07 09:06:07,450 - root - INFO - Python version: 3.13.3 (main, Apr  8 2025, 19:55:40) [GCC 14.2.0]
2025-07-07 09:06:07,450 - root - INFO - Environment debug info:
2025-07-07 09:06:07,450 - root - INFO -   Is Replit: False
2025-07-07 09:06:07,450 - root - INFO -   Replit URL: None
2025-07-07 09:06:07,450 - root - INFO - Initializing database...
2025-07-07 09:06:07,451 - root - INFO - Database initialized successfully
2025-07-07 09:06:07,451 - root - INFO - OpenAI API key loaded successfully
2025-07-07 09:06:07,451 - root - INFO - Creating Telegram application...
2025-07-07 09:06:07,497 - root - INFO - Telegram application created successfully
2025-07-07 09:06:07,497 - root - INFO - Registering handlers...
2025-07-07 09:06:07,498 - root - INFO - Handlers registered successfully
2025-07-07 09:06:07,498 - root - INFO - No webhook configured, will use polling mode
2025-07-07 09:06:07,498 - root - INFO - 📡 Starting polling mode...
2025-07-07 09:06:07,767 - httpx - INFO - HTTP Request: POST https://api.telegram.org/bot8082065832:AAFMg57PUuHJzTt2YavoqCK5pEBYlhpVdYg/getMe "HTTP/1.1 200 OK"
2025-07-07 09:06:07,857 - httpx - INFO - HTTP Request: POST https://api.telegram.org/bot8082065832:AAFMg57PUuHJzTt2YavoqCK5pEBYlhpVdYg/deleteWebhook "HTTP/1.1 200 OK"
2025-07-07 09:06:07,858 - telegram.ext.Application - INFO - Application started
2025-07-07 09:06:15,545 - httpx - INFO - HTTP Request: POST https://api.telegram.org/bot8082065832:AAFMg57PUuHJzTt2YavoqCK5pEBYlhpVdYg/getUpdates "HTTP/1.1 200 OK"
2025-07-07 09:06:15,545 - telegram.ext.Application - INFO - Application is stopping. This might take a moment.
2025-07-07 09:06:15,545 - telegram.ext.Application - INFO - Application.stop() complete
2025-07-07 09:06:15,546 - root - ERROR - Event loop conflict. Cannot run in this environment.
2025-07-07 09:06:15,556 - asyncio - ERROR - Task exception was never retrieved
future: <Task finished name='Task-1' coro=<main_async() done, defined at /workspace/main_replit.py:16> exception=SystemExit(1)>
Traceback (most recent call last):
  File "/workspace/main.py", line 245, in run_bot
    await app.run_polling(drop_pending_updates=True)
          ~~~~~~~~~~~~~~~^^^^^^^^^^^^^^^^^^^^^^^^^^^
  File "/home/ubuntu/.local/lib/python3.13/site-packages/telegram/ext/_application.py", line 837, in run_polling
    return self.__run(
           ~~~~~~~~~~^
        updater_coroutine=self.updater.start_polling(
        ^^^^^^^^^^^^^^^^^^^^^^^^^^^^^^^^^^^^^^^^^^^^^
    ...<9 lines>...
        close_loop=close_loop,
        ^^^^^^^^^^^^^^^^^^^^^^
    )
    ^
  File "/home/ubuntu/.local/lib/python3.13/site-packages/telegram/ext/_application.py", line 1077, in __run
    loop.close()
    ~~~~~~~~~~^^
  File "/usr/lib/python3.13/asyncio/unix_events.py", line 70, in close
    super().close()
    ~~~~~~~~~~~~~^^
  File "/usr/lib/python3.13/asyncio/selector_events.py", line 101, in close
    raise RuntimeError("Cannot close a running event loop")
RuntimeError: Cannot close a running event loop

During handling of the above exception, another exception occurred:

Traceback (most recent call last):
  File "/workspace/main_replit.py", line 32, in <module>
    main()
    ~~~~^^
  File "/workspace/main_replit.py", line 26, in main
    asyncio.run(main_async())
    ~~~~~~~~~~~^^^^^^^^^^^^^^
  File "/home/ubuntu/.local/lib/python3.13/site-packages/nest_asyncio.py", line 30, in run
    return loop.run_until_complete(task)
           ~~~~~~~~~~~~~~~~~~~~~~~^^^^^^
  File "/home/ubuntu/.local/lib/python3.13/site-packages/nest_asyncio.py", line 92, in run_until_complete
    self._run_once()
    ~~~~~~~~~~~~~~^^
  File "/home/ubuntu/.local/lib/python3.13/site-packages/nest_asyncio.py", line 133, in _run_once
    handle._run()
    ~~~~~~~~~~~^^
  File "/usr/lib/python3.13/asyncio/events.py", line 89, in _run
    self._context.run(self._callback, *self._args)
    ~~~~~~~~~~~~~~~~~^^^^^^^^^^^^^^^^^^^^^^^^^^^^^
  File "/usr/lib/python3.13/asyncio/tasks.py", line 293, in __step
    self.__step_run_and_handle_result(exc)
    ~~~~~~~~~~~~~~~~~~~~~~~~~~~~~~~~~^^^^^
  File "/usr/lib/python3.13/asyncio/tasks.py", line 304, in __step_run_and_handle_result
    result = coro.send(None)
  File "/workspace/main_replit.py", line 20, in main_async
    await run_bot()
  File "/workspace/main.py", line 249, in run_bot
    sys.exit(1)
    ~~~~~~~~^^^
SystemExit: 1
2025-07-07 09:19:59,606 - root - INFO - === QUIZ BOT STARTING ===
2025-07-07 09:19:59,606 - root - INFO - Python version: 3.13.3 (main, Apr  8 2025, 19:55:40) [GCC 14.2.0]
2025-07-07 09:19:59,606 - root - INFO - Environment debug info:
2025-07-07 09:19:59,606 - root - INFO -   Is Replit: False
2025-07-07 09:19:59,606 - root - INFO -   Replit URL: None
2025-07-07 09:19:59,606 - root - INFO - Initializing database...
2025-07-07 09:19:59,607 - root - INFO - Database initialized successfully
2025-07-07 09:19:59,607 - root - INFO - OpenAI API key loaded successfully
2025-07-07 09:19:59,607 - root - INFO - Creating Telegram application...
2025-07-07 09:19:59,664 - root - INFO - Telegram application created successfully
2025-07-07 09:19:59,664 - root - INFO - Registering handlers...
2025-07-07 09:19:59,665 - root - INFO - ✅ New unified settings handlers registered
2025-07-07 09:19:59,665 - root - INFO - Handlers registered successfully
2025-07-07 09:19:59,665 - root - INFO - No webhook configured, will use polling mode
2025-07-07 09:19:59,665 - root - INFO - 📡 Starting polling mode...
2025-07-07 09:19:59,916 - httpx - INFO - HTTP Request: POST https://api.telegram.org/bot8082065832:AAFMg57PUuHJzTt2YavoqCK5pEBYlhpVdYg/getMe "HTTP/1.1 200 OK"
2025-07-07 09:19:59,996 - httpx - INFO - HTTP Request: POST https://api.telegram.org/bot8082065832:AAFMg57PUuHJzTt2YavoqCK5pEBYlhpVdYg/deleteWebhook "HTTP/1.1 200 OK"
2025-07-07 09:19:59,997 - telegram.ext.Application - INFO - Application started
2025-07-07 09:20:07,654 - httpx - INFO - HTTP Request: POST https://api.telegram.org/bot8082065832:AAFMg57PUuHJzTt2YavoqCK5pEBYlhpVdYg/getUpdates "HTTP/1.1 200 OK"
2025-07-07 09:20:07,654 - telegram.ext.Application - INFO - Application is stopping. This might take a moment.
2025-07-07 09:20:07,655 - telegram.ext.Application - INFO - Application.stop() complete
2025-07-07 09:20:07,655 - root - ERROR - Event loop conflict. Cannot run in this environment.
2025-07-07 09:20:07,670 - asyncio - ERROR - Task exception was never retrieved
future: <Task finished name='Task-1' coro=<run_bot() done, defined at /workspace/main.py:168> exception=SystemExit(1)>
Traceback (most recent call last):
  File "/workspace/main.py", line 255, in run_bot
    await app.run_polling(drop_pending_updates=True)
          ~~~~~~~~~~~~~~~^^^^^^^^^^^^^^^^^^^^^^^^^^^
  File "/home/ubuntu/.local/lib/python3.13/site-packages/telegram/ext/_application.py", line 837, in run_polling
    return self.__run(
           ~~~~~~~~~~^
        updater_coroutine=self.updater.start_polling(
        ^^^^^^^^^^^^^^^^^^^^^^^^^^^^^^^^^^^^^^^^^^^^^
    ...<9 lines>...
        close_loop=close_loop,
        ^^^^^^^^^^^^^^^^^^^^^^
    )
    ^
  File "/home/ubuntu/.local/lib/python3.13/site-packages/telegram/ext/_application.py", line 1077, in __run
    loop.close()
    ~~~~~~~~~~^^
  File "/usr/lib/python3.13/asyncio/unix_events.py", line 70, in close
    super().close()
    ~~~~~~~~~~~~~^^
  File "/usr/lib/python3.13/asyncio/selector_events.py", line 101, in close
    raise RuntimeError("Cannot close a running event loop")
RuntimeError: Cannot close a running event loop

During handling of the above exception, another exception occurred:

Traceback (most recent call last):
  File "/workspace/main.py", line 310, in <module>
    main()
    ~~~~^^
  File "/workspace/main.py", line 277, in main
    asyncio.run(run_bot())
    ~~~~~~~~~~~^^^^^^^^^^^
  File "/home/ubuntu/.local/lib/python3.13/site-packages/nest_asyncio.py", line 30, in run
    return loop.run_until_complete(task)
           ~~~~~~~~~~~~~~~~~~~~~~~^^^^^^
  File "/home/ubuntu/.local/lib/python3.13/site-packages/nest_asyncio.py", line 92, in run_until_complete
    self._run_once()
    ~~~~~~~~~~~~~~^^
  File "/home/ubuntu/.local/lib/python3.13/site-packages/nest_asyncio.py", line 133, in _run_once
    handle._run()
    ~~~~~~~~~~~^^
  File "/usr/lib/python3.13/asyncio/events.py", line 89, in _run
    self._context.run(self._callback, *self._args)
    ~~~~~~~~~~~~~~~~~^^^^^^^^^^^^^^^^^^^^^^^^^^^^^
  File "/usr/lib/python3.13/asyncio/tasks.py", line 293, in __step
    self.__step_run_and_handle_result(exc)
    ~~~~~~~~~~~~~~~~~~~~~~~~~~~~~~~~~^^^^^
  File "/usr/lib/python3.13/asyncio/tasks.py", line 304, in __step_run_and_handle_result
    result = coro.send(None)
  File "/workspace/main.py", line 259, in run_bot
    sys.exit(1)
    ~~~~~~~~^^^
SystemExit: 1
2025-07-07 13:50:25,217 - root - INFO - === QUIZ BOT STARTING ===
2025-07-07 13:50:25,217 - root - INFO - Python version: 3.13.3 (main, Apr  8 2025, 19:55:40) [GCC 14.2.0]
2025-07-07 13:50:25,217 - root - INFO - Environment debug info:
2025-07-07 13:50:25,217 - root - INFO -   Is Replit: False
2025-07-07 13:50:25,217 - root - INFO -   Replit URL: None
2025-07-07 13:50:25,217 - root - INFO - Initializing database...
2025-07-07 13:50:25,217 - root - INFO - Database initialized successfully
2025-07-07 13:50:25,218 - root - ERROR - ❌ Telegram Bot Token not found! Please set it in Replit Secrets:
1. 🔒 Open Secrets tab in Replit
2. ➕ Add new secret: TELEGRAM_TOKEN = your_bot_token
3. 🔄 Restart the bot

Get token from @BotFather in Telegram
2025-07-07 13:50:25,230 - asyncio - ERROR - Task exception was never retrieved
future: <Task finished name='Task-1' coro=<run_bot() done, defined at /workspace/main.py:151> exception=SystemExit(1)>
Traceback (most recent call last):
  File "/workspace/main.py", line 308, in <module>
    main()
    ~~~~^^
  File "/workspace/main.py", line 272, in main
    asyncio.run(run_bot())
    ~~~~~~~~~~~^^^^^^^^^^^
  File "/home/ubuntu/.local/lib/python3.13/site-packages/nest_asyncio.py", line 30, in run
    return loop.run_until_complete(task)
           ~~~~~~~~~~~~~~~~~~~~~~~^^^^^^
  File "/home/ubuntu/.local/lib/python3.13/site-packages/nest_asyncio.py", line 92, in run_until_complete
    self._run_once()
    ~~~~~~~~~~~~~~^^
  File "/home/ubuntu/.local/lib/python3.13/site-packages/nest_asyncio.py", line 133, in _run_once
    handle._run()
    ~~~~~~~~~~~^^
  File "/usr/lib/python3.13/asyncio/events.py", line 89, in _run
    self._context.run(self._callback, *self._args)
    ~~~~~~~~~~~~~~~~~^^^^^^^^^^^^^^^^^^^^^^^^^^^^^
  File "/usr/lib/python3.13/asyncio/tasks.py", line 293, in __step
    self.__step_run_and_handle_result(exc)
    ~~~~~~~~~~~~~~~~~~~~~~~~~~~~~~~~~^^^^^
  File "/usr/lib/python3.13/asyncio/tasks.py", line 304, in __step_run_and_handle_result
    result = coro.send(None)
  File "/workspace/main.py", line 179, in run_bot
    sys.exit(1)
    ~~~~~~~~^^^
SystemExit: 1
2025-07-07 13:51:01,800 - root - INFO - === QUIZ BOT STARTING ===
2025-07-07 13:51:01,800 - root - INFO - Python version: 3.13.3 (main, Apr  8 2025, 19:55:40) [GCC 14.2.0]
2025-07-07 13:51:01,800 - root - INFO - Environment debug info:
2025-07-07 13:51:01,800 - root - INFO -   Is Replit: False
2025-07-07 13:51:01,800 - root - INFO -   Replit URL: None
2025-07-07 13:51:01,801 - root - INFO - Initializing database...
2025-07-07 13:51:01,801 - root - INFO - Database initialized successfully
2025-07-07 13:51:01,801 - root - ERROR - ❌ Telegram Bot Token not found! Please set it in Replit Secrets:
1. 🔒 Open Secrets tab in Replit
2. ➕ Add new secret: TELEGRAM_TOKEN = your_bot_token
3. 🔄 Restart the bot

Get token from @BotFather in Telegram
2025-07-07 13:51:01,809 - asyncio - ERROR - Task exception was never retrieved
future: <Task finished name='Task-1' coro=<run_bot() done, defined at /workspace/main.py:151> exception=SystemExit(1)>
Traceback (most recent call last):
  File "/workspace/main.py", line 308, in <module>
    main()
    ~~~~^^
  File "/workspace/main.py", line 272, in main
    asyncio.run(run_bot())
    ~~~~~~~~~~~^^^^^^^^^^^
  File "/home/ubuntu/.local/lib/python3.13/site-packages/nest_asyncio.py", line 30, in run
    return loop.run_until_complete(task)
           ~~~~~~~~~~~~~~~~~~~~~~~^^^^^^
  File "/home/ubuntu/.local/lib/python3.13/site-packages/nest_asyncio.py", line 92, in run_until_complete
    self._run_once()
    ~~~~~~~~~~~~~~^^
  File "/home/ubuntu/.local/lib/python3.13/site-packages/nest_asyncio.py", line 133, in _run_once
    handle._run()
    ~~~~~~~~~~~^^
  File "/usr/lib/python3.13/asyncio/events.py", line 89, in _run
    self._context.run(self._callback, *self._args)
    ~~~~~~~~~~~~~~~~~^^^^^^^^^^^^^^^^^^^^^^^^^^^^^
  File "/usr/lib/python3.13/asyncio/tasks.py", line 293, in __step
    self.__step_run_and_handle_result(exc)
    ~~~~~~~~~~~~~~~~~~~~~~~~~~~~~~~~~^^^^^
  File "/usr/lib/python3.13/asyncio/tasks.py", line 304, in __step_run_and_handle_result
    result = coro.send(None)
  File "/workspace/main.py", line 179, in run_bot
    sys.exit(1)
    ~~~~~~~~^^^
SystemExit: 1
2025-07-07 13:51:29,985 - root - INFO - === QUIZ BOT STARTING ===
2025-07-07 13:51:29,985 - root - INFO - Python version: 3.13.3 (main, Apr  8 2025, 19:55:40) [GCC 14.2.0]
2025-07-07 13:51:29,985 - root - INFO - Environment debug info:
2025-07-07 13:51:29,985 - root - INFO -   Is Replit: False
2025-07-07 13:51:29,985 - root - INFO -   Replit URL: None
2025-07-07 13:51:29,985 - root - INFO - Initializing database...
2025-07-07 13:51:29,985 - root - INFO - Database initialized successfully
2025-07-07 13:51:29,986 - root - ERROR - ❌ Telegram Bot Token not found! Please set it in Replit Secrets:
1. 🔒 Open Secrets tab in Replit
2. ➕ Add new secret: TELEGRAM_TOKEN = your_bot_token
3. 🔄 Restart the bot

Get token from @BotFather in Telegram
2025-07-07 13:51:29,994 - asyncio - ERROR - Task exception was never retrieved
future: <Task finished name='Task-1' coro=<run_bot() done, defined at /workspace/main.py:151> exception=SystemExit(1)>
Traceback (most recent call last):
  File "/workspace/main.py", line 308, in <module>
    main()
    ~~~~^^
  File "/workspace/main.py", line 272, in main
    asyncio.run(run_bot())
    ~~~~~~~~~~~^^^^^^^^^^^
  File "/home/ubuntu/.local/lib/python3.13/site-packages/nest_asyncio.py", line 30, in run
    return loop.run_until_complete(task)
           ~~~~~~~~~~~~~~~~~~~~~~~^^^^^^
  File "/home/ubuntu/.local/lib/python3.13/site-packages/nest_asyncio.py", line 92, in run_until_complete
    self._run_once()
    ~~~~~~~~~~~~~~^^
  File "/home/ubuntu/.local/lib/python3.13/site-packages/nest_asyncio.py", line 133, in _run_once
    handle._run()
    ~~~~~~~~~~~^^
  File "/usr/lib/python3.13/asyncio/events.py", line 89, in _run
    self._context.run(self._callback, *self._args)
    ~~~~~~~~~~~~~~~~~^^^^^^^^^^^^^^^^^^^^^^^^^^^^^
  File "/usr/lib/python3.13/asyncio/tasks.py", line 293, in __step
    self.__step_run_and_handle_result(exc)
    ~~~~~~~~~~~~~~~~~~~~~~~~~~~~~~~~~^^^^^
  File "/usr/lib/python3.13/asyncio/tasks.py", line 304, in __step_run_and_handle_result
    result = coro.send(None)
  File "/workspace/main.py", line 179, in run_bot
    sys.exit(1)
    ~~~~~~~~^^^
SystemExit: 1
2025-07-07 13:51:38,506 - root - INFO - === QUIZ BOT STARTING ===
2025-07-07 13:51:38,506 - root - INFO - Python version: 3.13.3 (main, Apr  8 2025, 19:55:40) [GCC 14.2.0]
2025-07-07 13:51:38,506 - root - INFO - Environment debug info:
2025-07-07 13:51:38,506 - root - INFO -   Is Replit: False
2025-07-07 13:51:38,506 - root - INFO -   Replit URL: None
2025-07-07 13:51:38,506 - root - INFO - Initializing database...
2025-07-07 13:51:38,507 - root - INFO - Database initialized successfully
2025-07-07 13:51:38,507 - root - INFO - OpenAI API key loaded successfully
2025-07-07 13:51:38,507 - root - INFO - Creating Telegram application...
2025-07-07 13:51:38,548 - root - INFO - Telegram application created successfully
2025-07-07 13:51:38,548 - root - INFO - Registering handlers...
2025-07-07 13:51:38,548 - root - INFO - ✅ Unified settings handler registered FIRST
2025-07-07 13:51:38,549 - root - INFO - Handlers registered successfully
2025-07-07 13:51:38,549 - root - INFO - No webhook configured, will use polling mode
2025-07-07 13:51:38,549 - root - INFO - 📡 Starting polling mode...
2025-07-07 13:51:38,855 - httpx - INFO - HTTP Request: POST https://api.telegram.org/bot8082065832:AAFMg57PUuHJzTt2YavoqCK5pEBYlhpVdYg/getMe "HTTP/1.1 200 OK"
2025-07-07 13:51:38,937 - httpx - INFO - HTTP Request: POST https://api.telegram.org/bot8082065832:AAFMg57PUuHJzTt2YavoqCK5pEBYlhpVdYg/deleteWebhook "HTTP/1.1 200 OK"
2025-07-07 13:51:38,937 - apscheduler.scheduler - INFO - Scheduler started
2025-07-07 13:51:38,938 - telegram.ext.Application - INFO - Application started
2025-07-07 13:51:43,389 - httpx - INFO - HTTP Request: POST https://api.telegram.org/bot8082065832:AAFMg57PUuHJzTt2YavoqCK5pEBYlhpVdYg/getUpdates "HTTP/1.1 409 Conflict"
2025-07-07 13:51:43,390 - telegram.ext.Application - ERROR - No error handlers are registered, logging exception.
Traceback (most recent call last):
  File "/home/ubuntu/.local/lib/python3.13/site-packages/telegram/ext/_utils/networkloop.py", line 115, in network_retry_loop
    if not await do_action():
           ^^^^^^^^^^^^^^^^^
  File "/home/ubuntu/.local/lib/python3.13/site-packages/telegram/ext/_utils/networkloop.py", line 108, in do_action
    return action_cb_task.result()
           ~~~~~~~~~~~~~~~~~~~~~^^
  File "/usr/lib/python3.13/asyncio/futures.py", line 199, in result
    raise self._exception.with_traceback(self._exception_tb)
  File "/usr/lib/python3.13/asyncio/tasks.py", line 304, in __step_run_and_handle_result
    result = coro.send(None)
  File "/home/ubuntu/.local/lib/python3.13/site-packages/telegram/ext/_updater.py", line 340, in polling_action_cb
    updates = await self.bot.get_updates(
              ^^^^^^^^^^^^^^^^^^^^^^^^^^^
    ...<3 lines>...
    )
    ^
  File "/home/ubuntu/.local/lib/python3.13/site-packages/telegram/ext/_extbot.py", line 669, in get_updates
    updates = await super().get_updates(
              ^^^^^^^^^^^^^^^^^^^^^^^^^^
    ...<9 lines>...
    )
    ^
  File "/home/ubuntu/.local/lib/python3.13/site-packages/telegram/_bot.py", line 4610, in get_updates
    await self._post(
    ^^^^^^^^^^^^^^^^^
    ...<7 lines>...
    ),
    ^
  File "/home/ubuntu/.local/lib/python3.13/site-packages/telegram/_bot.py", line 697, in _post
    return await self._do_post(
           ^^^^^^^^^^^^^^^^^^^^
    ...<6 lines>...
    )
    ^
  File "/home/ubuntu/.local/lib/python3.13/site-packages/telegram/ext/_extbot.py", line 369, in _do_post
    return await super()._do_post(
           ^^^^^^^^^^^^^^^^^^^^^^^
    ...<6 lines>...
    )
    ^
  File "/home/ubuntu/.local/lib/python3.13/site-packages/telegram/_bot.py", line 726, in _do_post
    result = await request.post(
             ^^^^^^^^^^^^^^^^^^^
    ...<6 lines>...
    )
    ^
  File "/home/ubuntu/.local/lib/python3.13/site-packages/telegram/request/_baserequest.py", line 197, in post
    result = await self._request_wrapper(
             ^^^^^^^^^^^^^^^^^^^^^^^^^^^^
    ...<7 lines>...
    )
    ^
  File "/home/ubuntu/.local/lib/python3.13/site-packages/telegram/request/_baserequest.py", line 374, in _request_wrapper
    raise exception
telegram.error.Conflict: Conflict: terminated by other getUpdates request; make sure that only one bot instance is running
2025-07-07 13:51:49,183 - httpx - INFO - HTTP Request: POST https://api.telegram.org/bot8082065832:AAFMg57PUuHJzTt2YavoqCK5pEBYlhpVdYg/getUpdates "HTTP/1.1 409 Conflict"
2025-07-07 13:51:49,183 - telegram.ext.Application - ERROR - No error handlers are registered, logging exception.
Traceback (most recent call last):
  File "/home/ubuntu/.local/lib/python3.13/site-packages/telegram/ext/_utils/networkloop.py", line 115, in network_retry_loop
    if not await do_action():
           ^^^^^^^^^^^^^^^^^
  File "/home/ubuntu/.local/lib/python3.13/site-packages/telegram/ext/_utils/networkloop.py", line 108, in do_action
    return action_cb_task.result()
           ~~~~~~~~~~~~~~~~~~~~~^^
  File "/usr/lib/python3.13/asyncio/futures.py", line 199, in result
    raise self._exception.with_traceback(self._exception_tb)
  File "/usr/lib/python3.13/asyncio/tasks.py", line 304, in __step_run_and_handle_result
    result = coro.send(None)
  File "/home/ubuntu/.local/lib/python3.13/site-packages/telegram/ext/_updater.py", line 340, in polling_action_cb
    updates = await self.bot.get_updates(
              ^^^^^^^^^^^^^^^^^^^^^^^^^^^
    ...<3 lines>...
    )
    ^
  File "/home/ubuntu/.local/lib/python3.13/site-packages/telegram/ext/_extbot.py", line 669, in get_updates
    updates = await super().get_updates(
              ^^^^^^^^^^^^^^^^^^^^^^^^^^
    ...<9 lines>...
    )
    ^
  File "/home/ubuntu/.local/lib/python3.13/site-packages/telegram/_bot.py", line 4610, in get_updates
    await self._post(
    ^^^^^^^^^^^^^^^^^
    ...<7 lines>...
    ),
    ^
  File "/home/ubuntu/.local/lib/python3.13/site-packages/telegram/_bot.py", line 697, in _post
    return await self._do_post(
           ^^^^^^^^^^^^^^^^^^^^
    ...<6 lines>...
    )
    ^
  File "/home/ubuntu/.local/lib/python3.13/site-packages/telegram/ext/_extbot.py", line 369, in _do_post
    return await super()._do_post(
           ^^^^^^^^^^^^^^^^^^^^^^^
    ...<6 lines>...
    )
    ^
  File "/home/ubuntu/.local/lib/python3.13/site-packages/telegram/_bot.py", line 726, in _do_post
    result = await request.post(
             ^^^^^^^^^^^^^^^^^^^
    ...<6 lines>...
    )
    ^
  File "/home/ubuntu/.local/lib/python3.13/site-packages/telegram/request/_baserequest.py", line 197, in post
    result = await self._request_wrapper(
             ^^^^^^^^^^^^^^^^^^^^^^^^^^^^
    ...<7 lines>...
    )
    ^
  File "/home/ubuntu/.local/lib/python3.13/site-packages/telegram/request/_baserequest.py", line 374, in _request_wrapper
    raise exception
telegram.error.Conflict: Conflict: terminated by other getUpdates request; make sure that only one bot instance is running
2025-07-07 13:51:53,544 - httpx - INFO - HTTP Request: POST https://api.telegram.org/bot8082065832:AAFMg57PUuHJzTt2YavoqCK5pEBYlhpVdYg/getUpdates "HTTP/1.1 200 OK"
2025-07-07 13:51:53,545 - telegram.ext.Application - INFO - Application is stopping. This might take a moment.
2025-07-07 13:51:53,545 - apscheduler.scheduler - INFO - Scheduler has been shut down
2025-07-07 13:51:53,555 - telegram.ext.Application - INFO - Application.stop() complete
2025-07-07 13:51:53,556 - root - ERROR - Event loop conflict. Cannot run in this environment.
2025-07-07 13:51:53,571 - asyncio - ERROR - Task exception was never retrieved
future: <Task finished name='Task-1' coro=<run_bot() done, defined at /workspace/main.py:151> exception=SystemExit(1)>
Traceback (most recent call last):
  File "/workspace/main.py", line 250, in run_bot
    await app.run_polling(drop_pending_updates=True)
          ~~~~~~~~~~~~~~~^^^^^^^^^^^^^^^^^^^^^^^^^^^
  File "/home/ubuntu/.local/lib/python3.13/site-packages/telegram/ext/_application.py", line 837, in run_polling
    return self.__run(
           ~~~~~~~~~~^
        updater_coroutine=self.updater.start_polling(
        ^^^^^^^^^^^^^^^^^^^^^^^^^^^^^^^^^^^^^^^^^^^^^
    ...<9 lines>...
        close_loop=close_loop,
        ^^^^^^^^^^^^^^^^^^^^^^
    )
    ^
  File "/home/ubuntu/.local/lib/python3.13/site-packages/telegram/ext/_application.py", line 1077, in __run
    loop.close()
    ~~~~~~~~~~^^
  File "/usr/lib/python3.13/asyncio/unix_events.py", line 70, in close
    super().close()
    ~~~~~~~~~~~~~^^
  File "/usr/lib/python3.13/asyncio/selector_events.py", line 101, in close
    raise RuntimeError("Cannot close a running event loop")
RuntimeError: Cannot close a running event loop

During handling of the above exception, another exception occurred:

Traceback (most recent call last):
  File "/workspace/main.py", line 308, in <module>
    main()
    ~~~~^^
  File "/workspace/main.py", line 272, in main
    asyncio.run(run_bot())
    ~~~~~~~~~~~^^^^^^^^^^^
  File "/home/ubuntu/.local/lib/python3.13/site-packages/nest_asyncio.py", line 30, in run
    return loop.run_until_complete(task)
           ~~~~~~~~~~~~~~~~~~~~~~~^^^^^^
  File "/home/ubuntu/.local/lib/python3.13/site-packages/nest_asyncio.py", line 92, in run_until_complete
    self._run_once()
    ~~~~~~~~~~~~~~^^
  File "/home/ubuntu/.local/lib/python3.13/site-packages/nest_asyncio.py", line 133, in _run_once
    handle._run()
    ~~~~~~~~~~~^^
  File "/usr/lib/python3.13/asyncio/events.py", line 89, in _run
    self._context.run(self._callback, *self._args)
    ~~~~~~~~~~~~~~~~~^^^^^^^^^^^^^^^^^^^^^^^^^^^^^
  File "/usr/lib/python3.13/asyncio/tasks.py", line 293, in __step
    self.__step_run_and_handle_result(exc)
    ~~~~~~~~~~~~~~~~~~~~~~~~~~~~~~~~~^^^^^
  File "/usr/lib/python3.13/asyncio/tasks.py", line 304, in __step_run_and_handle_result
    result = coro.send(None)
  File "/workspace/main.py", line 254, in run_bot
    sys.exit(1)
    ~~~~~~~~^^^
SystemExit: 1
2025-07-07 14:01:44,284 - root - INFO - === QUIZ BOT STARTING ===
2025-07-07 14:01:44,284 - root - INFO - Python version: 3.13.3 (main, Apr  8 2025, 19:55:40) [GCC 14.2.0]
2025-07-07 14:01:44,284 - root - INFO - Environment debug info:
2025-07-07 14:01:44,285 - root - INFO -   Is Replit: False
2025-07-07 14:01:44,285 - root - INFO -   Replit URL: None
2025-07-07 14:01:44,285 - root - INFO - Initializing database...
2025-07-07 14:01:44,285 - root - INFO - Database initialized successfully
2025-07-07 14:01:44,285 - root - ERROR - OpenAI configuration error: ❌ OpenAI API key not found! Please set it in Replit Secrets:
1. 🔒 Open Secrets tab in Replit
2. ➕ Add new secret: OPENAI_API_KEY = your_openai_key
3. 🔄 Restart the bot

Alternative: create openai_key.txt file (less secure)
2025-07-07 14:01:44,295 - asyncio - ERROR - Task exception was never retrieved
future: <Task finished name='Task-1' coro=<run_bot() done, defined at /workspace/main.py:151> exception=SystemExit(1)>
Traceback (most recent call last):
  File "/workspace/main.py", line 183, in run_bot
    config.load_openai_key()
    ~~~~~~~~~~~~~~~~~~~~~~^^
  File "/workspace/src/config.py", line 66, in load_openai_key
    raise ValueError(
    ...<5 lines>...
    )
ValueError: ❌ OpenAI API key not found! Please set it in Replit Secrets:
1. 🔒 Open Secrets tab in Replit
2. ➕ Add new secret: OPENAI_API_KEY = your_openai_key
3. 🔄 Restart the bot

Alternative: create openai_key.txt file (less secure)

During handling of the above exception, another exception occurred:

Traceback (most recent call last):
  File "/workspace/main.py", line 308, in <module>
    main()
    ~~~~^^
  File "/workspace/main.py", line 272, in main
    asyncio.run(run_bot())
    ~~~~~~~~~~~^^^^^^^^^^^
  File "/home/ubuntu/.local/lib/python3.13/site-packages/nest_asyncio.py", line 30, in run
    return loop.run_until_complete(task)
           ~~~~~~~~~~~~~~~~~~~~~~~^^^^^^
  File "/home/ubuntu/.local/lib/python3.13/site-packages/nest_asyncio.py", line 92, in run_until_complete
    self._run_once()
    ~~~~~~~~~~~~~~^^
  File "/home/ubuntu/.local/lib/python3.13/site-packages/nest_asyncio.py", line 133, in _run_once
    handle._run()
    ~~~~~~~~~~~^^
  File "/usr/lib/python3.13/asyncio/events.py", line 89, in _run
    self._context.run(self._callback, *self._args)
    ~~~~~~~~~~~~~~~~~^^^^^^^^^^^^^^^^^^^^^^^^^^^^^
  File "/usr/lib/python3.13/asyncio/tasks.py", line 293, in __step
    self.__step_run_and_handle_result(exc)
    ~~~~~~~~~~~~~~~~~~~~~~~~~~~~~~~~~^^^^^
  File "/usr/lib/python3.13/asyncio/tasks.py", line 304, in __step_run_and_handle_result
    result = coro.send(None)
  File "/workspace/main.py", line 187, in run_bot
    sys.exit(1)
    ~~~~~~~~^^^
SystemExit: 1
2025-07-09 10:04:24,640 - root - INFO - === QUIZ BOT STARTING ===
2025-07-09 10:04:24,641 - root - INFO - Python version: 3.13.3 (main, Apr  8 2025, 19:55:40) [GCC 14.2.0]
2025-07-09 10:04:24,641 - root - INFO - Environment debug info:
2025-07-09 10:04:24,641 - root - INFO -   Is Replit: False
2025-07-09 10:04:24,641 - root - INFO -   Replit URL: None
2025-07-09 10:04:24,641 - root - INFO - Initializing database...
2025-07-09 10:04:24,641 - root - INFO - Database initialized successfully
2025-07-09 10:04:24,641 - root - ERROR - ❌ Telegram Bot Token not found! Please set it in Replit Secrets:
1. 🔒 Open Secrets tab in Replit
2. ➕ Add new secret: TELEGRAM_TOKEN = your_bot_token
3. 🔄 Restart the bot

Get token from @BotFather in Telegram
2025-07-09 10:04:24,650 - asyncio - ERROR - Task exception was never retrieved
future: <Task finished name='Task-1' coro=<run_bot() done, defined at /workspace/main.py:133> exception=SystemExit(1)>
Traceback (most recent call last):
  File "/workspace/main.py", line 307, in <module>
    main()
    ~~~~^^
  File "/workspace/main.py", line 271, in main
    asyncio.run(run_bot())
    ~~~~~~~~~~~^^^^^^^^^^^
  File "/home/ubuntu/.local/lib/python3.13/site-packages/nest_asyncio.py", line 30, in run
    return loop.run_until_complete(task)
           ~~~~~~~~~~~~~~~~~~~~~~~^^^^^^
  File "/home/ubuntu/.local/lib/python3.13/site-packages/nest_asyncio.py", line 92, in run_until_complete
    self._run_once()
    ~~~~~~~~~~~~~~^^
  File "/home/ubuntu/.local/lib/python3.13/site-packages/nest_asyncio.py", line 133, in _run_once
    handle._run()
    ~~~~~~~~~~~^^
  File "/usr/lib/python3.13/asyncio/events.py", line 89, in _run
    self._context.run(self._callback, *self._args)
    ~~~~~~~~~~~~~~~~~^^^^^^^^^^^^^^^^^^^^^^^^^^^^^
  File "/usr/lib/python3.13/asyncio/tasks.py", line 293, in __step
    self.__step_run_and_handle_result(exc)
    ~~~~~~~~~~~~~~~~~~~~~~~~~~~~~~~~~^^^^^
  File "/usr/lib/python3.13/asyncio/tasks.py", line 304, in __step_run_and_handle_result
    result = coro.send(None)
  File "/workspace/main.py", line 161, in run_bot
    sys.exit(1)
    ~~~~~~~~^^^
SystemExit: 1
